Workbook

Sheet 统帅
A1: ID | B1: 是否展示 | C1: 肉鸽展示 | D1: 大圣名称 | F1: 排序 | G1: 大圣阵营 | H1: 初始皮肤id | I1: 额外皮肤Id | J1: 解锁段位 | K1: 部将解锁道具 | L1: 部将解锁道具消耗 | M1: 解锁消耗 | N1: 折扣文本 | O1: 机器人皮肤 | P1: 技能ID | Q1: 统帅技能是否在肉鸽玩法中展示 | R1: 卡牌组合推荐 | S1: 简介 | T1: 使用技巧 | U1: 大圣标签 | V1: 初始血量 | W1: 操作难度 | X1: AI选择权重 | Y1: 等级组 | Z1: 等级奖励 | AA1: 说明提示 | AB1: 关联卡 | AC1: 适配势力 | AD1: 三选一权重
A2: Id | B2: Show | C2: RogueShow | D2: Name | F2: Sort | G2: Chief_camp | H2: ChieflSkin_InitiaId | I2: ChiefSkin_ExtraId | J2: UnlcokRank | K2: UnlockItem | L2: UnlockNum | M2: UnlockCost | N2: PriceText | O2: AISkin | P2: SkillId | Q2: SkillIsShowinRouge | R2: CardCombo | S2: Brief | T2: HowToUse | U2: Label | V2: InitialHp | W2: DifficultyLevel | X2: AiPickValue | Y2: LevelGroup | Z2: LevelGiftGroup | AA2: InstructionPrompt | AB2: RelevantId | AC2: FullyCamp | AD2: PickValue
A3: 大圣ID | B3: 图鉴大圣是否展示 大圣选择是否出现 0否1是 | C3: 肉鸽模式是否展示大圣 0否1是 | F3: 小的在前 | G3: 大圣所属的阵营 同部将阵营 | H3: 初始就获得的 皮肤id | I3: 额外可解锁的 大圣皮肤id | J3: 战棋达到xx分数后解锁该英雄 -1为道具解锁 不填为默认解锁 | K3: 解锁部将使用的道具ID | L3: 解锁部将使用的道具数量 | M3: 解锁道具#数量；解锁道具#数量 | N3: 折扣文本 客户端显示的货币折扣 道具id#文字 | P3: 大圣技能表id | Q3: 通晒技能是否在肉鸽玩法中展示 | R3: 填写大圣推荐牌组表的id 可填多个，按顺序展示 | S3: 卡牌简介文本 | T3: 卡牌使用技巧文本 | U3: 填写标签定义表ID | V3: 大圣初始的血量值 | W3: 填写0~5 | X3: 机器人选择这名大圣的权重 | Z3: 英雄等级获得的奖励 等级奖励表组ID | AA3: 图鉴 - 说明提示 | AB3: 卡的类型#ID,ID;卡的类型#ID,ID 0=普通卡 1=法术 | AC3: 大圣适配的势力 | AD3: 三选一权重
A4: int | B4: int | C4: int | D4: string | F4: int | G4: int | H4: int | I4: list:int | J4: int | K4: int | L4: int | M4: list:string | N4: list:string | O4: int | P4: list:int | Q4: int | R4: list:int | S4: string | T4: string | U4: list:int | V4: int | W4: float | X4: int | Y4: int | Z4: int | AA4: string | AB4: string | AC4: list:int | AD4: int
A5: 备用行
A6: 3001 | B6: 1 | C6: 1 | D6: 菩提祖师 | E6: 0 | F6: 1 | G6: 6 | H6: 30010 | I6: 30011;30012 | O6: 30011 | P6: 30011 | Q6: 1 | R6: 1 | S6: 菩提祖师，隐居方寸山中，道法通天，深不可测。曾点化石猴孙悟空，授其变化腾云之术。只叹悟空得意忘形，祖师一语成谶：“日后惹祸，莫提我名！”拂袖而去，真乃仙人风范。 | T6: 阵容明确、操作简单的大圣。可对特定阵营施加群体增益。推荐登场同阵营卡组，花果山、天庭都非常合适。 | V6: 50 | W6: 1 | X6: 100 | Y6: 1 | Z6: 3001 | AC6: 6;2 | AD6: 10000
A7: 3002 | B7: 0 | C7: 0 | D7: 黄眉 | F7: 2 | G7: 6 | H7: 30020 | I7: 30021 | O7: 30021 | P7: 30021 | Q7: 1 | R7: 2 | S7: 这是卡牌的简介 | T7: 这是卡牌的使用技巧 | V7: 50 | X7: 0 | Y7: 1 | Z7: 3001 | AC7: 1
A8: 3003 | B8: 1 | C8: 1 | D8: 真武大帝 | E8: 灵玉买 | F8: 3 | G8: 6 | H8: 30030 | I8: 30031 | J8: -1 | K8: 5 | L8: 2500 | M8: 5#2500;8#680 | N8: 8#6折 | O8: 30031 | P8: 30031 | Q8: 1 | R8: 3 | S8: 真武大帝，亦称荡魔天尊，乃镇守北方的至高天神。披发跣足，踏龟蛇，统摄真武之位，专司剪伐天下妖魔。狂傲如齐天大圣，也曾借其名号震慑狮驼岭小妖。 | T8: 能够在前期轻松占据优势的大圣。推荐在左侧一号位放置有特殊进攻能力的部将，如【三太子】和【王灵官】等。 | V8: 50 | W8: 1.5 | X8: 100 | Y8: 1 | Z8: 3003 | AC8: 1;8 | AD8: 10000
A9: 3004 | B9: 1 | C9: 0 | D9: 金角大王 | E9: 0 | F9: 4 | G9: 6 | H9: 30040 | I9: 30041;30042 | O9: 30041 | P9: 30041;30042 | Q9: 1 | R9: 4 | S9: 金角大王，原是老君手下守炉童子，与银角共占平顶山。手拿玉净瓶，肩搭芭蕉扇，法宝众多，诡计多端。曾连施妙计擒唐僧，怎奈孙行者智高一筹，偷宝破法，终被老君收回炼丹炉。正是：仙童下界闹一场，机关算尽返原乡。 | T9: 阵容明确、操作简单的大圣，可快速提升特定部将属性。推荐狮驼岭阵容。 | V9: 50 | W9: 2 | X9: 100 | Y9: 1 | Z9: 3004 | AC9: 7 | AD9: 10000
A10: 3005 | B10: 0 | C10: 0 | D10: 太白金星 | F10: 5 | G10: 6 | H10: 30050 | I10: 30051 | O10: 30051 | P10: 30051 | Q10: 1 | R10: 5 | S10: 这是卡牌的简介 | T10: 这是卡牌的使用技巧 | V10: 50 | X10: 0 | Y10: 1 | Z10: 3001 | AC10: 1
A11: 3006 | B11: 1 | C11: 1 | D11: 黄风大圣 | E11: 10000 | F11: 6 | G11: 6 | H11: 30060 | I11: 30061 | J11: 10000 | O11: 30061 | P11: 30061;30062 | Q11: 1 | R11: 6 | S11: 本是灵山脚下得道的黄毛貂鼠，偷食琉璃盏内清油，占黄风岭为王。手执钢叉，最擅三昧神风，吹得天地昏暗，连齐天大圣都难睁火眼。幸遇灵吉菩萨，定风丹破法，方被收服。正是：风起黄沙遮日月，一粒宝丹定乾坤。 | T11: 以法术伤害见长的大圣，需要部将死亡以触发自身技能，与【残念】【业报】等效果相性较高。推荐使用灵山阵容。 | V11: 50 | W11: 1.5 | X11: 100 | Y11: 1 | Z11: 3006 | AC11: 3 | AD11: 10000
A12: 3007 | B12: 0 | C12: 0 | D12: 魔礼红 | F12: 7 | G12: 6 | H12: 30070 | I12: 30071 | O12: 30071 | P12: 30071 | Q12: 1 | R12: 7 | S12: 这是卡牌的简介 | T12: 这是卡牌的使用技巧 | V12: 50 | X12: 0 | Y12: 1 | Z12: 3001 | AC12: 1
A13: 3008 | B13: 0 | C13: 0 | D13: 金池长老 | F13: 8 | G13: 6 | H13: 30080 | I13: 30081;30082 | J13: -1 | K13: 3008 | L13: 1 | M13: 3008#1 | O13: 30081 | P13: 30081 | Q13: 1 | R13: 8 | S13: 这金池长老，寿高二百七十岁，观音院住持，平日念佛诵经，看似得道高僧。怎奈贪心作祟，见唐僧锦襕袈裟，竟起歹意，纵火谋财。反烧寺院，愧恨自尽。正是：修行百年一念贪，袈裟未得命先丧！ | T13: 这是卡牌的使用技巧 | V13: 50 | W13: 3 | X13: 100 | Y13: 1 | Z13: 3008 | AC13: 1
A14: 3009 | B14: 1 | C14: 0 | D14: 鬼子母神 | E14: 灵玉买 | F14: 9 | G14: 6 | H14: 30090 | I14: 30091 | J14: -1 | K14: 5 | L14: 2500 | M14: 5#2500;8#680 | N14: 8#6折 | O14: 30091 | P14: 30091;30092;30093 | Q14: 1 | R14: 9 | S14: 鬼子母神，又称爱子母，原为婆罗门教中的恶神，后被佛法教化，成为佛教护法二十四诸天之一的护法神，凡求子、护幼者，焚香祷告，有求必应。鬼母归善，慈悲为怀，一念转，业障消！ | T14: 综合性的大圣。既可以在利用召唤部将的属性加成取得优势，也可以在中后期召唤大量【护法】部将来触发多次触发【业报】效果或保护关键部将。 | V14: 50 | W14: 5 | X14: 100 | Y14: 1 | Z14: 3009 | AC14: 5 | AD14: 10000
A15: 3010 | B15: 0 | C15: 0 | D15: 嫦娥 | F15: 10 | G15: 6 | H15: 30100 | I15: 30101 | O15: 30101 | P15: 30101 | Q15: 1 | R15: 10 | S15: 这是卡牌的简介 | T15: 这是卡牌的使用技巧 | V15: 50 | X15: 0 | Y15: 1 | Z15: 3001 | AC15: 1
A16: 3011 | B16: 1 | C16: 1 | D16: 托塔天王 | E16: 七日庆典 | F16: 11 | G16: 6 | H16: 30110 | I16: 30111 | J16: -1 | K16: 3011 | L16: 1 | M16: 3011#1 | O16: 30111 | P16: 30111;30112 | Q16: 1 | R16: 11 | S16: 托塔天王，本名李靖，三坛海会大神之父，掌天兵天将，威风凛凛。左手托玲珑宝塔，镇邪压魔。虽为天庭重臣，却忠孝难全，父子恩怨，说来令人唏嘘！正是：塔在手，威自生，一将镇乾坤！ | T16: 和【护盾】拥有最佳相性的大圣。可以尝试以【李天王】和【三太子】为核心，打造终极阵容。 | V16: 50 | W16: 4 | X16: 100 | Y16: 1 | Z16: 3011 | AC16: 8 | AD16: 10000
A17: 3012 | B17: 1 | C17: 0 | D17: 玉皇大帝 | E17: 10000 | F17: 12 | G17: 6 | H17: 30120 | I17: 30121;30122 | O17: 30121 | P17: 30121 | Q17: 1 | R17: 12 | S17: 玉皇大帝端坐那凌霄宝殿之上，傲视九天，统御三界，执掌乾坤。一声令下，万神朝拜，雷部奔走，星宿听调。虽曾被悟空搅乱蟠桃会，然稳坐中天，不动如山。正是：一道圣旨传九霄，三界安泰仰龙颜。 | T17: 适合所有阵容，但对使用者具有高判断力要求的大圣。将哪一个关键部将变为金卡，是能够取胜的关键决定。 | V17: 50 | W17: 4.5 | X17: 100 | Y17: 1 | Z17: 3012 | AC17: 999 | AD17: 10000
A18: 3013 | B18: 0 | C18: 0 | D18: 月老 | F18: 13 | G18: 6 | H18: 30130 | I18: 30131 | O18: 30131 | P18: 30131;30132 | Q18: 1 | R18: 13 | S18: 那二郎真君，清源妙道，额生天眼，手执三尖两刃刀，哮天神犬随身伴。听调不听宣，傲骨嶙峋！曾战齐天大圣，斗法云端，三百回合不分胜负。真个是：神仙俊杰，威震灌江口！ | T18: 这是卡牌的使用技巧 | V18: 50 | X18: 0 | Y18: 1 | Z18: 3001 | AC18: 1
A19: 3014 | B19: 1 | C19: 0 | D19: 骊山圣女 | E19: 2000 | F19: 14 | G19: 6 | H19: 30140 | I19: 30141;30142 | J19: 2000 | O19: 30141 | P19: 30141;30142 | Q19: 1 | R19: 14 | S19: 骊山老母，乃上古女仙，居骊山之巅，神通广大，慈悲为怀。常化凡人点化众生，传艺授法，助女将破敌。曾化身寡妇，试禅心，显慧眼。正是：白发慈颜藏道妙，指点迷津度万灵。 | T19: 适合所有阵容的大圣，但使用难度较高，非常考验使用者对神通法术的熟悉程度。 | V19: 50 | W19: 3.5 | X19: 100 | Y19: 1 | Z19: 3014 | AC19: 6;9 | AD19: 10000
A20: 3015 | B20: 1 | C20: 0 | D20: 苏妲己 | E20: 人民币买 | F20: 15 | G20: 6 | H20: 30150 | I20: 30151 | J20: -1 | K20: 3015 | L20: 1 | M20: 3015#1 | O20: 30151 | P20: 30151 | Q20: 1 | R20: 15 | S20: 本是千年狐妖附体，容颜倾城绝世，媚骨天生。凭一身魅惑妖术蛊惑商纣，迷乱君心，祸乱朝纲，残害忠良。心机阴诡，手段狠辣，搅动殷商山河动荡，乃是封神乱世中倾国祸世的绝代妖姬。 | T20: 适合所有阵容的大圣，但使用难度较高，非常考验使用者对合成哪些关键金卡的判断。 | V20: 50 | W20: 5 | X20: 100 | Y20: 1 | Z20: 3015 | AB20: 0#1061 | AC20: 999 | AD20: 11000
A21: 3016 | B21: 1 | C21: 0 | D21: 玉面狐狸 | E21: 10000 | F21: 16 | G21: 6 | H21: 30160 | I21: 30161;30162 | O21: 30161 | P21: 30161 | Q21: 1 | R21: 16 | S21: 万岁狐王之女，招赘牛魔王为夫，居积雷山摩云洞。生得千娇百媚，却心高气傲，仗势欺人。后因夫君恋上铁扇公主，又惹孙行者寻衅，家破人亡，香消玉殒。正是：红颜薄命狐作女，情海翻波祸自招。 | T21: 适合所有阵容的大圣，但需要使用者观察下一个对手的阵容，并养成控制费用的好习惯。 | V21: 50 | W21: 5 | X21: 100 | Y21: 1 | Z21: 3016 | AC21: 999 | AD21: 10000
A22: 3017 | B22: 1 | C22: 0 | D22: 太白金星 | E22: 2000 | F22: 17 | G22: 6 | H22: 30170 | I22: 30171 | J22: 2000 | O22: 30171 | P22: 30171 | Q22: 1 | R22: 17 | S22: 白须飘飘，仙风道骨，掌天庭机要，常奉玉帝之命，往来凡间仙界。三请孙悟空，言辞和善；调停纷争，老成持重。看似慈祥老臣，实乃洞明世故、周旋天机的明白人！正是：一杖扶云传圣令，和风化雨稳天庭。 | T22: 适合所有阵容的大圣，但使用难度较高。其技能使其拥有更大的机会拿到关键部将，但次数限制也要求玩家对当前局势有足够的判断力。 | V22: 50 | W22: 1 | X22: 100 | Y22: 1 | Z22: 3017 | AC22: 999 | AD22: 10000
A23: 3018 | B23: 1 | C23: 0 | D23: 钟馗 | E23: 0 | F23: 18 | G23: 6 | H23: 30180 | I23: 30181 | O23: 30181 | P23: 30181 | Q23: 1 | R23: 18 | S23: 且看这钟馗爷，铁面虬髯，怒目如电，头戴个乌纱破帽。原是唐时才子，因貌丑被黜，愤而撞阶，天帝感其刚烈，封为驱魔帝君。世人敬其，常言：魑魅魍魉莫敢近，真是人间阎王爷！ | T23: 无需操作的大圣，可稳定施加群体增益。适合以【协战】为核心的卡组，推荐使用花果山、天庭阵容。 | V23: 50 | W23: 2 | X23: 100 | Y23: 1 | Z23: 3018 | AC23: 6;8 | AD23: 10000
A24: 3019 | B24: 1 | C24: 0 | D24: 斗战胜佛 | E24: 0 | F24: 19 | G24: 6 | H24: 30190 | I24: 30191 | O24: 30190 | P24: 30192 | Q24: 1 | R24: 19 | S24: 齐天大圣孙悟空，大闹天宫，威震三界，经九九八十一难，护唐僧取经成功，终证正果，受封“斗战胜佛”！金箍一戴，万邪退散，火眼金睛照破妖魔。正是：昔日顽猴今作佛，灵山宝刹放光明。 | T24: 需要在前期通过战斗不断累积优势的大圣，适合以【协战】为核心的花果山阵容，也可以累积优势后转成其他阵容。 | V24: 50 | W24: 3 | X24: 100 | Y24: 1 | Z24: 3019 | AC24: 6 | AD24: 10000
A25: 3020 | B25: 1 | C25: 1 | D25: 石矶娘娘 | E25: 8000 | F25: 20 | G25: 6 | H25: 30200 | I25: 30201 | J25: 8000 | O25: 30201 | P25: 30201;30202;30203 | Q25: 1 | R25: 20 | S25: 石矶娘娘，乃天地灵石得道成仙，隐居骷髅山白骨洞府。容颜冷艳绝尘，性情孤高桀骜，精通阴玄诡异道法。不循仙门礼法，行事随性刚烈，身负灵石本源修为，神通莫测，傲然立于三界，搅动仙尘风云。 | T25: 以法术伤害见长的大圣，前期哪怕部将质量不高，也可以在交战中取得优势。推荐使用灵山阵容。 | V25: 50 | W25: 4 | X25: 100 | Y25: 1 | Z25: 3020 | AC25: 3 | AD25: 10000
A26: 3021 | B26: 1 | C26: 0 | D26: 西王母 | E26: 灵玉买 | F26: 21 | G26: 6 | H26: 30210 | I26: 30211;30212;30213 | J26: -1 | K26: 5 | L26: 2500 | M26: 5#2500;8#680 | N26: 8#6折 | O26: 30211 | P26: 30211;30212 | Q26: 1 | R26: 21 | S26: 那瑶池西王母，凤冠霞帔，掌长生蟠桃，开琼筵宴群仙。一果延寿千载，一宴定劫轮回。威仪赫赫，慈中带严，实乃女仙之首，万灵之母！世人赞其曰：蟠桃核里三千劫，金簪划处即天涯。莫问瑶池真颜色，半是昆仑半是沙。 | T26: 适合所有阵容的大圣。其大圣技能可以提前找到关键的高星部将，但非常考验玩家对部将星级的熟悉程度。 | V26: 50 | W26: 5 | X26: 100 | Y26: 1 | Z26: 3021 | AC26: 999 | AD26: 10000
A27: 3022 | B27: 0 | C27: 0 | D27: 魔礼青 | F27: 22 | G27: 6 | H27: 30220 | I27: 30221 | O27: 30221 | P27: 30221 | Q27: 1 | R27: 22 | S27: 这是卡牌的简介 | T27: 这是卡牌的使用技巧 | V27: 50 | X27: 0 | Y27: 1 | Z27: 3001 | AC27: 1
A28: 3023 | B28: 0 | C28: 0 | D28: 文财神 | F28: 23 | G28: 6 | H28: 30230 | I28: 30231 | O28: 30231 | P28: 30231;30232 | Q28: 1 | R28: 23 | S28: 这位老爷，头戴宰相帽，身披锦绣袍，手捧如意元宝，笑迎八方财源！原是商朝贤臣比干，赤胆忠心，无心不偏——民间尊为文财神，专管人间富贵利禄。求财者焚香礼拜，但行善事，福泽自来！ | T28: 这是卡牌的使用技巧 | V28: 50 | W28: 4 | X28: 0 | Y28: 1 | Z28: 3023 | AC28: 1
A29: 3024 | B29: 1 | C29: 1 | D29: 文财神 | E29: 灵玉买 | F29: 24 | G29: 6 | H29: 30230 | I29: 30231 | J29: -1 | K29: 5 | L29: 2500 | M29: 5#2500;8#680 | N29: 8#6折 | O29: 30231 | P29: 30241 | Q29: 1 | R29: 24 | S29: 这位老爷，头戴宰相帽，身披锦绣袍，正所谓：手捧如意金元宝，笑迎四面八方财！原是商朝贤臣比干，赤胆忠心，无心不偏——民间尊为文财神，专管人间富贵利禄。求财者焚香礼拜，但行善事，福泽自来！ | T29: 在经济方面拥有优势的大圣。可以多选取具有【登场】、【购买】效果的部将，从而充分地利用大圣技能。 | V29: 50 | W29: 3 | X29: 100 | Y29: 1 | Z29: 3024 | AC29: 8;7 | AD29: 10000
A30: 3025 | B30: 1 | C30: 1 | D30: 镇元子 | E30: 人民币买 | F30: 25 | G30: 6 | H30: 30250 | I30: 30251 | J30: -1 | K30: 3025 | L30: 1 | M30: 3025#1 | O30: 30251 | P30: 30251 | Q30: 1 | R30: 25 | S30: 此人神通广大，与三清称兄道弟。人参果树一朝被毁，他袖袍一抖，乾坤倒转，把个齐天大圣擒了又擒。后观音救活仙树，他哈哈一笑，竟与悟空结为兄弟！真个是：道高龙虎伏，德重鬼神钦。 | T30: 在前期具有一定优势的大圣。在不同的阶段，选择合适的【后援】部将，是取胜的关键。配合【禄星】可多次触发效果。推荐使用花果山、龙宫阵容。 | V30: 50 | W30: 2 | X30: 100 | Y30: 1 | Z30: 3025 | AC30: 6;4 | AD30: 11000
A31: 3026 | B31: 1 | C31: 0 | D31: 银角大王 | E31: 4000 | F31: 26 | G31: 6 | H31: 30260 | I31: 30261;30262 | J31: 4000 | O31: 30261 | P31: 30261 | Q31: 1 | R31: 26 | S31: 银角大王原是老君座下看炉的童子，却偷了紫金葫芦、玉净瓶，下界为妖。与兄金角占山为王，手段狠辣，连擒八戒沙僧。谁料葫芦反被悟空骗去，终被老君收回。正是：宝贝虽多难逆命，一场富贵化云烟！ | T31: 可以在不损失任何属性的情况下清理场上不需要的部将。推荐狮驼岭阵容。 | V31: 50 | W31: 1 | X31: 100 | Y31: 1 | Z31: 3026 | AC31: 7;6;8 | AD31: 10000
A32: 3027 | B32: 0 | C32: 0 | D32: 混世魔王 | F32: 27 | G32: 6 | H32: 30270 | I32: 30271 | O32: 30271 | P32: 30271 | Q32: 1 | R32: 27 | S32: 这是卡牌的简介 | T32: 这是卡牌的使用技巧 | V32: 50 | X32: 0 | Y32: 1 | Z32: 3001 | AC32: 1
A33: 3028 | B33: 1 | C33: 0 | D33: 观音大神 | E33: 灵玉买 | F33: 28 | G33: 6 | H33: 30280 | I33: 30281;30282 | J33: -1 | K33: 5 | L33: 2500 | M33: 5#2500;8#680 | N33: 8#6折 | O33: 30281 | P33: 30281 | Q33: 1 | R33: 28 | S33: 且说那南海观音大神，慈眉善目，手持净瓶杨柳，坐莲台，驾祥云。闻声救苦，解难消灾，点化悟空，护佑取经。正是：千手千眼照乾坤，一念慈悲度众生！ | T33: 操作简单的、在寻找部将方面拥有优势的大圣。其技能可以让他以更高的频率寻找当前阶段的关键部将，多用神通是使其技能收益最大化的关键。 | V33: 50 | W33: 1.5 | X33: 100 | Y33: 1 | Z33: 3028 | AC33: 9 | AD33: 10000
A34: 3029 | B34: 0 | C34: 0 | D34: 女儿国王 | F34: 29 | G34: 6 | H34: 30290 | I34: 30291 | O34: 30291 | P34: 30291 | Q34: 1 | R34: 29 | S34: 这是卡牌的简介 | T34: 这是卡牌的使用技巧 | V34: 50 | X34: 0 | Y34: 1 | Z34: 3001 | AC34: 1
A35: 3030 | B35: 1 | C35: 0 | D35: 混世魔王 | E35: 0 | F35: 30 | G35: 6 | H35: 30300 | I35: 30301;30302 | O35: 30301 | P35: 30301 | Q35: 1 | R35: 30 | S35: 这混世魔王，强占水帘洞天，欺占群猴，手段凶残。不料大圣学成归来，一棒将其碾作亡魂。虽是修为低微的宵小之辈，却是大圣血光初试第一人。有诗赞曰：魔头猖狂终授首，大圣初战定根基。 | T35: 无需操作的大圣，适合以【协战】为核心的卡组，推荐使用花果山、天庭。 | V35: 50 | W35: 2.5 | X35: 100 | Y35: 1 | Z35: 3030 | AC35: 6;8 | AD35: 10000
A36: 3031 | B36: 1 | C36: 0 | D36: 黄狮精 | E36: 0 | F36: 31 | G36: 6 | H36: 30310 | I36: 30311 | O36: 30311 | P36: 30311 | Q36: 1 | R36: 31 | S36: 黄狮精乃九灵元圣徒孙，占据豹头山虎口洞为巢。此妖痴迷神兵，盗走悟空师兄弟兵器，却行事独特——付钱买猪羊，开“钉耙会”。虽非大奸大恶之徒，却横死大圣棒下，令人不禁扼腕。正是：钉耙犹带耕云梦，翻作豹头山上尘。 | T36: 适合所有阵容的大圣，大圣技能可在前期提升战斗力，在中后期可养成特定的部将。 | V36: 50 | W36: 3.5 | X36: 100 | Y36: 1 | Z36: 3031 | AC36: 999 | AD36: 10000
A37: 3032 | B37: 0 | C37: 0 | D37: 西王母 | F37: 32 | G37: 6 | H37: 30320 | I37: 30321 | O37: 30321 | P37: 30321;30322 | Q37: 1 | R37: 32 | S37: 这是卡牌的简介 | T37: 这是卡牌的使用技巧 | V37: 50 | X37: 0 | Y37: 1 | Z37: 3001 | AC37: 1
A38: 3033 | B38: 1 | C38: 0 | D38: 孟婆 | E38: 灵玉买 | F38: 33 | G38: 6 | H38: 30330 | I38: 30331 | J38: -1 | K38: 5 | L38: 2500 | M38: 5#2500;8#680 | N38: 8#6折 | O38: 30331 | P38: 30331;30332 | Q38: 1 | R38: 33 | S38: 地府掌管轮回之使，驻在奈何桥头忘川彼岸。一碗孟婆汤，管他是王侯将相、凡夫走卒，自此前尘尽忘，六道轮回去也！世人常道：一勺汤尽千般泪，三生爱恨化云烟。 | T38: 适合以【登场】部将为辅助核心的大圣，搭配【福星】可多次触发效果。推荐天庭、狮驼岭阵容。 | V38: 50 | W38: 4.5 | X38: 0 | Y38: 1 | Z38: 3033 | AC38: 8;7 | AD38: 10000
A39: 3034 | B39: 1 | C39: 0 | D39: 女儿国王 | E39: 七日签到 | F39: 34 | G39: 6 | H39: 30340 | I39: 30341;30342 | J39: -1 | K39: 3034 | L39: 1 | M39: 3034#1 | O39: 30341 | P39: 30341 | Q39: 1 | R39: 34 | S39: 西梁女国那女王娘娘，生得闭月羞花，性情温婉多情。遇唐僧师徒，一见倾心，愿以倾国之富，换君共度此生。虽终未能挽留圣僧西去，一片痴情仍感天动地。正是：柔情似水女儿国，一段姻缘天难全。 | T39: 适合所有阵容的大圣，额外的免费刷新使其比其他大圣有更大机会购买到心仪的部将。 | V39: 50 | W39: 4.5 | X39: 100 | Y39: 1 | Z39: 3034 | AC39: 999 | AD39: 10000
A40: 3035 | B40: 0 | C40: 0 | D40: 弥勒佛 | F40: 35 | G40: 6 | H40: 30350 | I40: 30351;30352 | O40: 30351 | P40: 30351 | Q40: 1 | R40: 35 | S40: 这是卡牌的简介 | T40: 这是卡牌的使用技巧 | V40: 50 | X40: 0 | Y40: 1 | Z40: 3001 | AC40: 1
...

Sheet 统帅技能
A1: 技能ID | B1: 技能组 | D1: 技能名称 | E1: 技能副标题 | F1: AI策略类型 | G1: AI策略参数 | H1: 技能描述 | I1: 技能简版内容 | J1: 技能详情内容 | K1: 是否有技能详情 | N1: 技能图标 | O1: 技能表现 | P1: 技能类型 | Q1: 技能消耗 | R1: 选择目标 | S1: 拥有特性 | T1: 先机顺序 | U1: 解锁技能的商店等级 | V1: 解锁技能的回合 | W1: 限制使用次数 | X1: 使用次数减耗 | Y1: 升级类型 | Z1: 升级参数 | AA1: 抉择卡牌技能ID | AB1: 被动触发类型 | AC1: 技能参数 | AD1: 参数描述 | AE1: 填充参数显示 | AF1: 技能填充参数 | AG1: 客户端额外参数 | AH1: 默认填充参数 | AJ1: 技能喊话ID
A2: Id | B2: SkillGroup | D2: SkillName | E2: SkillTitle | F2: AIStrategyType | G2: AIStrategyParam | H2: SkillDesc | I2: SkillDetails | J2: SkillSimple | K2: HaveDetails | N2: SkillIcon | O2: Perform_Skill | P2: SkillType | Q2: SkillCost | R2: SelectTargetId | S2: FeatureID | T2: Sort | U2: UnlockSkillShopLv | V2: UnlockSkillRound | W2: Limit | X2: UseReduceCost | Y2: LvUpTyper | Z2: LvUpParam | AA2: SlectSkillID | AB2: TriggerType | AC2: SkillParam | AD2: Desc | AE2: ShowUseNumByParams | AF2: ExtParams | AG2: ClientExtParams | AH2: DefaultParams | AJ2: TaskId
B3: 服务器 技能组 | F3: 查看批注 | G3: 1、数量 2、数量 3、特性id 4、特性id | H3: 参数在战斗中由服务器提供 在展示时,根据配置的默认填充参数展示 说明 文本规则：指定/随机-行为 -数量 -敌我 -单位类型 - 具体属性 标红规则：特性标红，指定部将、神通标红 其他规则：不写回合等于永久，写了回合就是限时 位置规则：不写就是场上，写了商店、手牌才会包含 指定规则：没写随机就是指定 ，写了其他就是不包含自身 常用名次：自身 友方部将 敌方部将 所有 其他 我方大圣 敌方大圣 | I3: 大圣选择界面 技能描述读这里 | J3: 点击详情后 技能描述读这里 | K3: 0 没有 1 有 有的话技能图标后显示详情按钮 | O3: 技能的表现 表现id | P3: 0被动 1主动 | Q3: 主动显示 消耗金币 被动不显示 | R3: 该卡操作时 选择目标id 不配是直接用 | S3: 统帅特性 | U3: 商店X级时 解锁使用该技能 | V3: 第几回合时 解锁技能 | W3: 总次数限制 | X3: 仅限 技能用N次后 技能消耗-1点 | Y3: 技能升级的类型 1、使用次数升级 2、商店等级升级 3、触发使用升级 | Z3: 根据升级类型 1、使用次数 2、商店等级 3、触发次数 | AA3: 使用后需要进行抉择的技能 | AB3: 1、战斗开始前 2、商店升级触发 3、战斗中召唤部将 4、特性触发 5、使用卡牌 6、出售 7、购买卡牌 8、切换回合(同回营) 9、统帅死亡时 10、到上阵队伍 11、召唤特定势力部将 12、击杀敌方部将 13、开局时 14、大圣受到任意伤害时 15、友方阵亡N个部将触发 | AE3: 通过技能参数显示技能使用次数使用 | AF3: 服务器下发的参数 | AG3: Administrator: 在默认填充参数的基础上，额外需要展示的参数 use:当前使用次数 left:剩余次数 magic:法强 shop：根据商店增加次数 cd:技能冷却 | AH3: 当无法获得 服务器提供的参数时 参数展示为默认值 | AI3: 备注 策划需要需要展示的参数 | AJ3: 释放技能时，播放的喊话内容ID Z_战斗——技能喊话ID
A4: int | B4: int | D4: string | E4: string | F4: int | G4: list:int | H4: string | I4: string | J4: string | K4: int | N4: string | O4: int | P4: int | Q4: int | R4: int | S4: int | T4: int | U4: int | V4: int | W4: int | X4: int | Y4: int | Z4: int | AA4: list:int | AB4: int | AC4: string | AD4: string | AE4: int | AF4: string | AG4: list:string | AH4: list:int | AJ4: int
A5: 备用行
A6: 30011 | B6: 1 | C6: =_xlfn.XLOOKUP(VALUE(LEFT(A6,4)),[1]统帅!A:A,[1]统帅!D:D,9999) -> 菩提祖师 | D6: 布道 | E6: 主动 | F6: 3 | G6: 6 | H6: 使1个部将与其同阵营的部将+{0}/+{1}(每购买2张花果山/大唐阵营部将额外+1/+1) | I6: 使1个部将与其同阵营的部将+1/+1 | J6: 使1个部将与其同阵营的部将+1/+1(每购买2张花果山/大唐阵营部将额外+1/+1) | K6: 1 | L6: masterskill_3001 | M6: =K6&L6 -> 1masterskill_3001 | N6: Card/masterskill_3001 | O6: 3001 | P6: 1 | Q6: 0 | R6: 201 | AC6: 1#1;2;2#6;1#1 | AD6: 攻击#血量;购买数量;势力类型#势力类型;额外加的攻击;额外加的血 | AF6: 2参数， 攻击，血量 | AH6: 1;1 | AI6: 2参数， 攻击，血量 | AJ6: 30011
A7: 30021 | B7: 2 | C7: =_xlfn.XLOOKUP(VALUE(LEFT(A7,4)),[1]统帅!A:A,[1]统帅!D:D,9999) -> 黄眉 | D7: 九首 | E7: 主动 | F7: 2 | G7: 4 | H7: 使用后,获得商店内全部卡牌(每过1回合,以及每购买1张罗刹部将,技能费用-1) | I7: 使用后,获得商店内全部卡牌(每过1回合,以及每购买1张罗刹部将,技能费用-1) | M7: =K7&L7 | N7: Card/img-jineng2 | O7: 3002 | P7: 1 | Q7: 11 | AC7: 1 | AD7: 参数势力类型
A8: 30031 | B8: 3 | C8: 真武大帝 | D8: 真武 | E8: 被动 | H8: <color=#d77b28>先手</color>:使最左侧部将本回合获得<color=#d77b28>狂怒</color>;+{0}/+{1}(随回合数提升,每回合提高+1/+1) | I8: <color=#d77b28>先手</color>:使最左侧部将本回合获得<color=#d77b28>狂怒</color>与+3/+3 | J8: <color=#d77b28>先手</color>:使最左侧部将本回合获得<color=#d77b28>狂怒</color>与+3/+3(随回合数提升,每回合提高+1/+1) | K8: 1 | L8: masterskill_3003 | M8: 1masterskill_3003 | N8: Card/masterskill_3003 | O8: 3003 | P8: 0 | S8: 9 | T8: 1 | AC8: 10;3#3 | AD8: 特性ID;攻击#血量 | AF8: 2参数， 攻击，血量 | AH8: 3;3 | AI8: 2参数， 攻击，血量 | AJ8: 30031
A9: 30041 | B9: 4 | C9: 金角大王 | D9: 玉净瓶 | E9: 主动 | F9: 1 | G9: 3 | H9: 使商店部将+1/+1(剩余{0}次,使用6次后费用+1) | I9: 使商店部将+1/+1(可用10次,6次后费用+1) | J9: 使商店部将+1/+1(可用10次,6次后费用+1) | K9: 1 | L9: masterskill_3004 | M9: Card/masterskill_3004 | N9: Card/masterskill_3004 | O9: 3004 | P9: 1 | Q9: 0 | W9: 10 | Y9: 1 | Z9: 6 | AC9: 1;1 | AD9: 参数+1/+1 | AF9: 1参数， 剩余次数 | AG9: left | AH9: 10 | AI9: 2参数， 剩余次数 | AJ9: 30041
A10: 30042 | B10: 4 | C10: 金角大王 | D10: 玉净瓶 | E10: 主动 | F10: 1 | G10: 3 | H10: 使商店部将+1/+1(剩余{0}次,使用6次后费用+1) | I10: 使商店部将+1/+1(可用10次,6次后费用+1) | J10: 使商店部将+1/+1(可用10次,6次后费用+1) | L10: masterskill_3004 | M10: Card/masterskill_3004 | N10: Card/masterskill_3004 | O10: 3004 | P10: 1 | Q10: 1 | W10: 10 | AC10: 1;1 | AD10: 参数+1/+1 | AF10: 1参数， 剩余次数 | AG10: left | AH10: 10 | AI10: 2参数， 剩余次数 | AJ10: 30041
A11: 30051 | B11: 5 | C11: =_xlfn.XLOOKUP(VALUE(LEFT(A11,4)),[1]统帅!A:A,[1]统帅!D:D,9999) -> 太白金星 | D11: 诏安 | E11: 主动 | F11: 1 | G11: 1 | H11: 挑选1张具有登场效果的部将(使用{0}/8次后,技能费用-1) | I11: 使用后,挑选1张具有登场效果的部将(使用<color=#d77b28>{0}/8</color>次后,技能费用-1) | M11: =K11&L11 | N11: Card/img-jineng1 | O11: 3005 | P11: 1 | Q11: 2 | X11: 8 | AG11: use | AH11: 0 | AI11: 1参数，当前使用次数
A12: 30061 | B12: 6 | C12: =_xlfn.XLOOKUP(VALUE(LEFT(A12,4)),[1]统帅!A:A,[1]统帅!D:D,9999) -> 黄风大圣 | D12: 飞沙 | E12: 被动 | H12: <color=#d77b28>业报(3)</color>:对所有敌方部将造成2点伤害,商店等级5升级;(<color=#d77b28>灵力</color>:+{0}) | I12: <color=#d77b28>业报(3)</color>:对所有敌方部将造成2点伤害 | J12: <color=#d77b28>业报(3)</color>:对所有敌方部将造成2点伤害(商店等级5时提升3点伤害) | K12: 1 | L12: masterskill_3006 | M12: =K12&L12 -> 1masterskill_3006 | N12: Card/masterskill_3006 | O12: 3006 | P12: 0 | Q12: 0 | S12: 14 | Y12: 2 | Z12: 5 | AB12: 4 | AC12: 3;2 | AD12: 业报数量;法术伤害 | AF12: 1参数，灵力 | AG12: magic | AH12: 0 | AI12: 1参数，灵力 | AJ12: 30061
A13: 30062 | B13: 6 | C13: =_xlfn.XLOOKUP(VALUE(LEFT(A13,4)),[1]统帅!A:A,[1]统帅!D:D,9999) -> 黄风大圣 | D13: 飞沙 | E13: 被动 | H13: <color=#d77b28>业报(3)</color>:对所有敌方部将造成6点伤害;(<color=#d77b28>灵力</color>:+{0}) | I13: <color=#d77b28>业报(3)</color>:对所有敌方部将造成6点伤害 | L13: masterskill_3006 | M13: =K13&L13 -> masterskill_3006 | N13: Card/masterskill_3006 | O13: 3006 | S13: 14 | U13: 5 | AB13: 4 | AC13: 3;6 | AD13: 业报数量;法术伤害 | AF13: 1参数，灵力 | AG13: magic | AH13: 0 | AI13: 1参数，灵力 | AJ13: 30061
A14: 30071 | B14: 7 | C14: =_xlfn.XLOOKUP(VALUE(LEFT(A14,4)),[1]统帅!A:A,[1]统帅!D:D,9999) -> 魔礼红 | D14: 混元伞 | E14: 被动 | H14: 每次升级商店后,挑选1张当前商店等级的部将(提升商店至2级,3级的费用+1;提升商店至4级,5级,6级的费用+2) | I14: 每次升级商店后,挑选1张当前商店等级的部将(提升商店至2级,3级的费用+1;提升商店至4级,5级,6级的费用+2) | M14: =K14&L14 | N14: Card/img-jineng3 | O14: 3007 | P14: 0 | AB14: 2 | AC14: 2#1;3#1;4#2;5#2;6#2 | AD14: 商店等级#增加的升级费用
A15: 30081 | B15: 8 | C15: =_xlfn.XLOOKUP(VALUE(LEFT(A15,4)),[1]统帅!A:A,[1]统帅!D:D,9999) -> 金池长老 | D15: 袈裟 | E15: 主动 | F15: 1 | G15: 1 | H15: 使用后,获得1张<color=#d77b28>【金币】</color>,<color=#d77b28>{0}%</color>概率额外再获得1张(每次提升商店等级,概率提高10%) | I15: 使用后,获得1张<color=#d77b28>【金币】</color>,<color=#d77b28>{0}%</color>概率额外再获得1张(每次提升商店等级,概率提高10%) | L15: masterskill_3008 | M15: =K15&L15 -> masterskill_3008 | N15: Card/masterskill_3008 | O15: 3008 | P15: 1 | Q15: 0 | AC15: 1011 | AD15: 锦囊ID | AF15: 1参数，概率(数值：10到100) | AH15: 0 | AI15: 1参数，概率(数值：10到100) | AJ15: 30081
A16: 30091 | B16: 9 | C16: =_xlfn.XLOOKUP(VALUE(LEFT(A16,4)),[1]统帅!A:A,[1]统帅!D:D,9999) -> 鬼子母神 | D16: 六道 | E16: 被动 | H16: 战斗中召唤部将时,使其获得<color=#d77b28>护法</color>,+{0}/+{1}(商店等级3/5级时效果提升+1/+1) | I16: 战斗中召唤部将时,使其获得<color=#d77b28>护法</color>,+1/+1 | J16: 战斗中召唤部将时,使其获得<color=#d77b28>护法</color>,+1/+1(商店等级3/5级时效果提升+1/+1) | K16: 1 | L16: masterskill_3009 | M16: =K16&L16 -> 1masterskill_3009 | N16: Card/masterskill_3009 | O16: 3009 | P16: 0 | Y16: 2 | Z16: 3 | AB16: 3 | AC16: 2;1#0 | AD16: 特性ID;攻击;血量 | AF16: 2参数， 攻击，血量 | AH16: 1;0 | AI16: 2参数， 攻击，血量 | AJ16: 30091
A17: 30092 | B17: 9 | C17: =_xlfn.XLOOKUP(VALUE(LEFT(A17,4)),[1]统帅!A:A,[1]统帅!D:D,9999) -> 鬼子母神 | D17: 六道 | E17: 被动 | H17: 战斗中召唤部将时,使其获得<color=#d77b28>护法</color>,+{0}/+{1}(商店等级3/5级时效果提升+1/+1) | I17: 战斗中召唤部将时,使其获得<color=#d77b28>护法</color>,+2/+2 | J17: 战斗中召唤部将时,使其获得<color=#d77b28>护法</color>,+2/+2(商店等级3/5级时效果提升+1/+1) | K17: 1 | L17: masterskill_3009 | M17: =K17&L17 -> 1masterskill_3009 | N17: Card/masterskill_3009 | O17: 3009 | P17: 0 | U17: 3 | Y17: 2 | Z17: 5 | AB17: 3 | AC17: 2;1#1 | AD17: 特性ID;攻击;血量 | AF17: 2参数， 攻击，血量 | AH17: 1;1 | AI17: 2参数， 攻击，血量 | AJ17: 30091
A18: 30093 | B18: 9 | C18: =_xlfn.XLOOKUP(VALUE(LEFT(A18,4)),[1]统帅!A:A,[1]统帅!D:D,9999) -> 鬼子母神 | D18: 六道 | E18: 被动 | H18: 战斗中召唤部将时,使其获得<color=#d77b28>护法</color>,+{0}/+{1}(商店等级3/5级时效果提升+1/+1) | I18: 战斗中召唤部将时,使其获得<color=#d77b28>护法</color>,+3/+3 | J18: 战斗中召唤部将时,使其获得<color=#d77b28>护法</color>,+3/+3(商店等级3/5级时效果提升+1/+1) | K18: 1 | L18: masterskill_3009 | M18: =K18&L18 -> 1masterskill_3009 | N18: Card/masterskill_3009 | O18: 3009 | P18: 0 | U18: 5 | AB18: 3 | AC18: 2;2#2 | AD18: 特性ID;攻击;血量 | AF18: 2参数， 攻击，血量 | AH18: 2;2 | AI18: 2参数， 攻击，血量 | AJ18: 30091
A19: 30101 | B19: 10 | C19: =_xlfn.XLOOKUP(VALUE(LEFT(A19,4)),[1]统帅!A:A,[1]统帅!D:D,9999) -> 嫦娥 | D19: 月华 | E19: 主动 | F19: 1 | G19: 1 | H19: 使用后,挑选上一名对手的1个部将的基础版本(使用<color=#d77b28>{0}/4</color>次后,技能费用-1) | I19: 使用后,挑选上一名对手的1个部将的基础版本(使用<color=#d77b28>{0}/4</color>次后,技能费用-1) | L19: masterskill_3010 | M19: =K19&L19 -> masterskill_3010 | N19: Card/masterskill_3010 | O19: 3010 | P19: 1 | Q19: 2 | X19: 4 | AG19: use | AH19: 0 | AI19: 1参数，当前使用次数
A20: 30111 | B20: 11 | C20: =_xlfn.XLOOKUP(VALUE(LEFT(A20,4)),[1]统帅!A:A,[1]统帅!D:D,9999) -> 托塔天王 | D20: 镇守 | E20: 主动 | F20: 4 | G20: 5 | H20: 使1个部将获得<color=#d77b28>护盾</color>,并使具有<color=#d77b28>护盾</color>的部将+2/+2({0}/8次后费用+1) | I20: 使1个部将获得<color=#d77b28>护盾</color>,并使具有<color=#d77b28>护盾</color>的部将+2/+2(8/8次后费用+1) | L20: masterskill_3011 | M20: =K20&L20 -> masterskill_3011 | N20: Card/masterskill_3011 | O20: 3011 | P20: 1 | Q20: 1 | R20: 204 | Y20: 1 | Z20: 8 | AC20: 5;2#2 | AD20: 特性ID;攻击;血量 | AF20: 1参数 次数 | AG20: use | AH20: 0 | AI20: 1参数，当前使用次数 | AJ20: 30111
A21: 30112 | B21: 11 | C21: =_xlfn.XLOOKUP(VALUE(LEFT(A21,4)),[1]统帅!A:A,[1]统帅!D:D,9999) -> 托塔天王 | D21: 镇守 | E21: 主动 | F21: 4 | G21: 5 | H21: 使1个部将获得<color=#d77b28>护盾</color>,并使具有<color=#d77b28>护盾</color>的部将+2/+2({0}/8次后费用+1) | I21: 使1个部将获得<color=#d77b28>护盾</color>,并使具有<color=#d77b28>护盾</color>的部将+2/+2(8/8次后费用+1) | L21: masterskill_3011 | M21: =K21&L21 -> masterskill_3011 | N21: Card/masterskill_3011 | O21: 3011 | P21: 1 | Q21: 2 | R21: 204 | AC21: 5;2#2 | AD21: 特性ID;攻击;血量 | AF21: 1参数 次数 | AG21: use | AH21: 0 | AI21: 1参数，当前使用次数 | AJ21: 30111
A22: 30121 | B22: 12 | C22: =_xlfn.XLOOKUP(VALUE(LEFT(A22,4)),[1]统帅!A:A,[1]统帅!D:D,9999) -> 玉皇大帝 | D22: 圣谕 | E22: 主动 | F22: 5 | H22: 使1个部将获得+5/+5,并使其永久变为金卡;剩余({0}/2次) | I22: 使1个部将获得+5/+5,并使其永久变为金卡;剩余2次 | L22: masterskill_3012 | M22: =K22&L22 -> masterskill_3012 | N22: Card/masterskill_3012 | O22: 3012 | P22: 1 | Q22: 0 | R22: 202 | W22: 2 | AC22: 5;5 | AD22: 攻击力，生命值 | AF22: 1参数 次数 | AG22: left | AH22: 2 | AI22: 1参数，剩余次数 | AJ22: 30121
A23: 30131 | B23: 13 | C23: =_xlfn.XLOOKUP(VALUE(LEFT(A23,4)),[1]统帅!A:A,[1]统帅!D:D,9999) -> 月老 | D23: 红线 | E23: 主动 | F23: 1 | G23: 1 | H23: 使用后,随机获得商店内的1个部将(使用<color=#d77b28>{0}/9</color>次后,技能升级) | I23: 使用后,随机获得商店内的1个部将(使用<color=#d77b28>{0}/9</color>次后,技能升级) | M23: =K23&L23 | N23: Card/img-jineng1 | O23: 3013 | P23: 1 | Q23: 1 | Y23: 1 | Z23: 9 | AC23: 1;1 | AD23: 类型1纯随机#获得卡牌的属性倍数 | AG23: use | AH23: 0 | AI23: 1参数，当前使用次数
A24: 30132 | B24: 13 | C24: =_xlfn.XLOOKUP(VALUE(LEFT(A24,4)),[1]统帅!A:A,[1]统帅!D:D,9999) -> 月老 | D24: 红线 | E24: 主动 | F24: 1 | G24: 1 | H24: 使用后,获得商店内的1个星级最高的部将,并使其属性翻倍 | I24: 使用后,获得商店内的1个星级最高的部将,并使其属性翻倍 | M24: =K24&L24 | N24: Card/img-jineng1 | O24: 3013 | P24: 1 | Q24: 1 | AC24: 2;2 | AD24: 类型2最高星随机#获得卡牌的属性倍数
A25: 30141 | B25: 14 | C25: 骊山圣女 | D25: 道源 | E25: 主动 | F25: 1 | G25: 1 | H25: 挑选1张神通 | I25: 挑选1张神通 | L25: masterskill_3014 | M25: masterskill_3014 | N25: Card/masterskill_3014 | O25: 3014 | P25: 1 | Q25: 0 | AJ25: 30141
A26: 30142 | B26: 14 | C26: =_xlfn.XLOOKUP(VALUE(LEFT(A26,4)),[1]统帅!A:A,[1]统帅!D:D,9999) -> 骊山圣女 | D26: 道源 | E26: 主动 | F26: 1 | G26: 1 | H26: 挑选1张神通({0}/4次后费用+1) | I26: 挑选1张<color=#d77b28>神通</color>(4次后费用+1) | L26: masterskill_3014 | M26: =K26&L26 -> masterskill_3014 | N26: Card/masterskill_3014 | O26: 3014 | P26: 1 | Q26: 1 | AF26: 1参数 次数 | AG26: use | AH26: 0 | AI26: 1参数，当前使用次数 | AJ26: 30141
A27: 30151 | B27: 15 | C27: =_xlfn.XLOOKUP(VALUE(LEFT(A27,4)),[1]统帅!A:A,[1]统帅!D:D,9999) -> 六耳猕猴 | D27: 倾城 | E27: 主动 | F27: 1 | G27: 1 | H27: 获得1张<color=#d77b28>百面千相</color>(剩余{0}次;商店3级解锁) | I27: 获得1张<color=#d77b28>百面千相</color>(剩余4次) | J27: 获得1张<color=#d77b28>百面千相</color>(剩余{0}次;商店3级解锁) | K27: 1 | L27: masterskill_3015 | M27: =K27&L27 -> 1masterskill_3015 | N27: Card/masterskill_3015 | O27: 3015 | P27: 1 | Q27: 0 | U27: 3 | W27: 4 | AC27: 1061 | AG27: left | AH27: 4 | AI27: 1参数，剩余次数 | AJ27: 30151
A28: 30161 | B28: 16 | C28: =_xlfn.XLOOKUP(VALUE(LEFT(A28,4)),[1]统帅!A:A,[1]统帅!D:D,9999) -> 玉面狐狸 | D28: 魅惑 | E28: 主动 | F28: 1 | G28: 1 | H28: 本回合获得<color=#d77b28>先手</color>:召唤对手1个最高星级部将的普通卡进入战场,并获得该部将(若敌方没有部将则获得1张广结仙友1) | I28: 本回合获得<color=#d77b28>先手</color>:召唤对手1个最高星级部将的普通卡进入战场,并获得该部将(若敌方没有部将则获得1张广结仙友1) | L28: masterskill_3016 | M28: =K28&L28 -> masterskill_3016 | N28: Card/masterskill_3016 | O28: 3016 | P28: 1 | Q28: 1 | T28: 1 | AC28: 9;1041 | AD28: 特性ID;若没有部将则给与的神通ID | AJ28: 30161
A29: 30171 | B29: 17 | C29: =_xlfn.XLOOKUP(VALUE(LEFT(A29,4)),[1]统帅!A:A,[1]统帅!D:D,9999) -> 太白金星 | D29: 诏安 | E29: 主动 | F29: 1 | G29: 1 | H29: 挑选1个当前商店等级的部将(剩余{0}次) | I29: 挑选1个当前商店等级的部将(剩余6次) | M29: =K29&L29 | N29: Card/masterskill_3017 | O29: 3017 | P29: 1 | Q29: 1 | W29: 6 | AG29: left;use | AH29: 6;0 | AI29: 2参数，剩余次数，当前使用次数 | AJ29: 30171
A30: 30181 | B30: 18 | C30: =_xlfn.XLOOKUP(VALUE(LEFT(A30,4)),[1]统帅!A:A,[1]统帅!D:D,9999) -> 钟馗 | D30: 鬼令 | E30: 被动 | H30: <color=#d77b28>先手</color>:使场上所有友方部将+{0}攻击(每次升级商店提升+1) | I30: <color=#d77b28>先手</color>:使场上所有友方部将+2攻击 | J30: <color=#d77b28>先手</color>:使场上所有友方部将+2攻击(每次升级商店提升+1) | K30: 1 | L30: masterskill_3018 | M30: =K30&L30 -> 1masterskill_3018 | N30: Card/masterskill_3018 | O30: 3018 | P30: 0 | AB30: 1 | AF30: 1参数 商店等级 | AG30: left | AH30: 2 | AI30: 1参数，商店等级 | AJ30: 30181
A31: 30191 | B31: 19 | C31: =_xlfn.XLOOKUP(VALUE(LEFT(A31,4)),[1]统帅!A:A,[1]统帅!D:D,9999) -> 斗战胜佛 | D31: 齐天 | E31: 被动 | H31: 使所有友方部将获得<color=#d77b28>斗战</color>:自身+1攻击力(商店等级到达4级时,技能升级) | I31: 所有友方部将获得<color=#d77b28>斗战</color>:自身永久获得<color=#d77b28>+1</color>攻击力(商店等级到达<color=#d77b28>4级</color>时,技能升级) | L31: masterskill_3019 | M31: =K31&L31 -> masterskill_3019 | N31: Card/masterskill_3019 | O31: 3019 | P31: 0 | Y31: 2 | Z31: 4 | AB31: 1 | AC31: 30001 | AJ31: 30191
A32: 30192 | B32: 19 | C32: 白猿 | D32: 斗战 | E32: 被动 | H32: 友方部将获得<color=#d77b28>斗战</color>:自身+1/+1;<color=#d77b28>斗战</color>:进行攻击,被攻击后存活时触发 | I32: 友方部将获得<color=#d77b28>斗战</color>:自身+1/+1 | J32: 友方部将获得<color=#d77b28>斗战</color>:自身+1/+1;<color=#d77b28>斗战</color>:进行攻击,被攻击后存活时触发 | K32: 1 | L32: masterskill_3019 | M32: =K32&L32 -> 1masterskill_3019 | N32: Card/masterskill_3019 | O32: 3019 | P32: 0 | AB32: 1 | AC32: 30003 | AJ32: 30192
A33: 30201 | B33: 20 | C33: 石矶娘娘 | D33: 紫电 | E33: 被动 | H33: <color=#ff2d2d>先手</color>:对随机1个敌方部将造成1点伤害,次数取决于你上场战斗中部将死亡数量;商店等级3升级;(<color=#d77b28>灵力</color>:+{0}) | I33: <color=#ff2d2d>先手</color>:对随机1个敌方部将造成1点伤害,次数取决于你上场战斗中部将死亡数量 | J33: <color=#ff2d2d>先手</color>:对敌方随机1个部将造成1点伤害,次数取决于你上场战斗中部将死亡数量(商店等级3和5时提升1点伤害) | K33: 1 | L33: masterskill_3020 | M33: =K33&L33 -> 1masterskill_3020 | N33: Card/masterskill_3020 | O33: 3020 | P33: 0 | S33: 9 | T33: 1 | Y33: 2 | Z33: 3 | AB33: 4 | AC33: 9;1 | AF33: 1参数，灵力 | AG33: magic | AH33: 0 | AI33: 1参数，灵力 | AJ33: 30201
A34: 30202 | B34: 20 | C34: 石矶娘娘 | D34: 紫电 | E34: 被动 | H34: <color=#ff2d2d>先手</color>:对随机1个敌方部将造成2点伤害,次数取决于你上场战斗中部将死亡数量;商店等级5升级;(<color=#d77b28>灵力</color>:+{0}) | I34: <color=#ff2d2d>先手</color>:对随机1个敌方部将造成2点伤害,次数取决于你上场战斗中部将死亡数量 | J34: <color=#ff2d2d>先手</color>:对敌方随机1个部将造成2点伤害,次数取决于你上场战斗中部将死亡数量;商店等级3和5时提升1点伤害;(灵力:<color=#d77b28>+{0}</color>) | K34: 1 | L34: masterskill_3020 | M34: =K34&L34 -> 1masterskill_3020 | N34: Card/masterskill_3020 | O34: 3020 | P34: 0 | S34: 9 | T34: 1 | U34: 3 | Y34: 2 | Z34: 5 | AB34: 4 | AC34: 9;2 | AF34: 1参数，灵力 | AG34: magic | AH34: 0 | AI34: 1参数，灵力 | AJ34: 30201
A35: 30203 | B35: 20 | C35: 石矶娘娘 | D35: 紫电 | E35: 被动 | H35: <color=#ff2d2d>先手</color>:对随机1个敌方部将造成3点伤害,次数取决于你上场战斗中部将死亡数量(<color=#d77b28>灵力</color>:+{0}) | I35: <color=#ff2d2d>先手</color>:对随机1个敌方部将造成3点伤害,次数取决于你上场战斗中部将死亡数量 | J35: <color=#ff2d2d>先手</color>:对敌方随机1个部将造成3点伤害,次数取决于你上场战斗中部将死亡数量;商店等级3和5时提升1点伤害;(灵力:<color=#d77b28>+{0}</color>) | K35: 1 | L35: masterskill_3020 | M35: =K35&L35 -> 1masterskill_3020 | N35: Card/masterskill_3020 | O35: 3020 | P35: 0 | S35: 9 | T35: 1 | U35: 5 | AB35: 4 | AC35: 9;3 | AF35: 1参数，灵力 | AG35: magic | AH35: 0 | AI35: 1参数，灵力 | AJ35: 30201
A36: 30211 | B36: 21 | C36: =_xlfn.XLOOKUP(VALUE(LEFT(A36,4)),[1]统帅!A:A,[1]统帅!D:D,9999) -> 西王母 | D36: 蟠桃 | E36: 主动 | F36: 1 | G36: 1 | H36: 使1个商店中的部将变形为星级+1的随机部将({0}/6次后可对上阵部将生效,费用+1) | I36: 使1个商店中的部将变形为星级+1的随机部将(6次后可对上阵部将生效,费用+1) | L36: masterskill_3021 | M36: =K36&L36 -> masterskill_3021 | N36: Card/masterskill_3021 | O36: 3021 | P36: 1 | Q36: 0 | R36: 203 | Y36: 1 | Z36: 6 | AG36: use | AH36: 0 | AI36: 1参数，当前使用次数 | AJ36: 30211
A37: 30212 | B37: 21 | C37: =_xlfn.XLOOKUP(VALUE(LEFT(A37,4)),[1]统帅!A:A,[1]统帅!D:D,9999) -> 西王母 | D37: 蟠桃 | E37: 主动 | F37: 1 | G37: 1 | H37: 使1个商店中或上阵中的部将变形为星级+1的随机部将 | I37: 使1个商店中或上阵中的部将变形为星级+1的随机部将 | L37: masterskill_3021 | M37: =K37&L37 -> masterskill_3021 | N37: Card/masterskill_3021 | O37: 3021 | P37: 1 | Q37: 1 | R37: 204 | AJ37: 30212
A38: 30221 | B38: 22 | C38: =_xlfn.XLOOKUP(VALUE(LEFT(A38,4)),[1]统帅!A:A,[1]统帅!D:D,9999) -> 魔礼青 | D38: 青云剑 | E38: 被动 | H38: 每部署1张部将牌至交战区:商店升级费用-1 | I38: 每部署1张部将牌至交战区:商店升级费用-1 | M38: =K38&L38 | N38: Card/img-jineng2 | O38: 3022 | P38: 0 | AB38: 5
A39: 30231 | B39: 23 | C39: =_xlfn.XLOOKUP(VALUE(LEFT(A39,4)),[1]统帅!A:A,[1]统帅!D:D,9999) -> 文财神 | D39: 财神 | E39: 主动 | F39: 1 | G39: 1 | H39: 使用后,下回合获得<color=#d77b28>{0}</color>枚【金币】(使用<color=#d77b28>{1}/6</color>次后,技能效果升级) | I39: 使用后,下回合获得<color=#d77b28>{0}</color>枚【金币】(使用<color=#d77b28>{1}/6</color>次后,技能效果升级) | L39: masterskill_3023 | M39: =K39&L39 -> masterskill_3023 | N39: Card/masterskill_3023 | O39: 3023 | P39: 1 | Q39: 1 | X39: 6 | AC39: 2 | AG39: use | AH39: 2;0 | AI39: 1参数，当前使用次数 | AJ39: 30231
A40: 30232 | B40: 23 | C40: =_xlfn.XLOOKUP(VALUE(LEFT(A40,4)),[1]统帅!A:A,[1]统帅!D:D,9999) -> 文财神 | D40: 财神 | E40: 主动 | F40: 1 | G40: 1 | H40: 使用后,下回合获得<color=#d77b28>{0}</color>枚【金币】 | I40: 使用后,下回合获得<color=#d77b28>{0}</color>枚【金币】 | L40: masterskill_3023 | M40: =K40&L40 -> masterskill_3023 | N40: Card/masterskill_3023 | O40: 3023 | P40: 1 | Q40: 1 | AC40: 2 | AJ40: 30232
...

Sheet 统帅熟练度等级
A1: ID | B1: 等级图标 | C1: 等级组 | D1: 等级 | E1: 需要经验
A2: Id | B2: LvIcon | C2: LevelGroup | D2: Level | E2: NeedExp
A3: 熟练度等级 | B3: 熟练度等级对应的图标 | D3: 实际使用的等级 | E3: 升到下一级经验
A4: int | B4: string | C4: int | D4: int | E4: int
A5: 备用行
A6: 1 | C6: 1 | D6: 1 | E6: 100
A7: 2 | C7: 1 | D7: 2 | E7: 100
A8: 3 | C8: 1 | D8: 3 | E8: 100
A9: 4 | C9: 1 | D9: 4 | E9: 100
A10: 5 | C10: 1 | D10: 5 | E10: 150
A11: 6 | C11: 1 | D11: 6 | E11: 150
A12: 7 | C12: 1 | D12: 7 | E12: 150
A13: 8 | C13: 1 | D13: 8 | E13: 150
A14: 9 | C14: 1 | D14: 9 | E14: 200
A15: 10 | C15: 1 | D15: 10 | E15: 200
A16: 11 | C16: 1 | D16: 11 | E16: 200
A17: 12 | C17: 1 | D17: 12 | E17: 200
... A104: 99 | C104: 1 | D104: 99 | E104: 1300
A105: 100 | C105: 1 | D105: 100

Sheet 统帅等级奖励
A1: ID | C1: 奖励组 | D1: 获得等级 | E1: 奖励
A2: ID | C2: GiftGroup | D2: GetLevel | E2: Gift
A3: 等级ID | C3: 大圣通过该组确定使用哪个奖励数据 | D3: 奖励在第N级可以获得 | E3: 填写到这级给的奖励道具ID#数量;
A4: int | C4: int | D4: int | E4: string
A5: 备用行
A6: 300101 | B6: 菩提祖师 | C6: 3001 | D6: 10 | E6: 8#5
A7: 300102 | B7: 菩提祖师 | C7: 3001 | D7: 20 | E7: 8#10
A8: 300103 | B8: 菩提祖师 | C8: 3001 | D8: 30 | E8: 8#10
A9: 300104 | B9: 菩提祖师 | C9: 3001 | D9: 40 | E9: 8#10
A10: 300105 | B10: 菩提祖师 | C10: 3001 | D10: 50 | E10: 8#5
A11: 300106 | B11: 菩提祖师 | C11: 3001 | D11: 60 | E11: 8#10
A12: 300107 | B12: 菩提祖师 | C12: 3001 | D12: 70 | E12: 8#10
A13: 300108 | B13: 菩提祖师 | C13: 3001 | D13: 80 | E13: 8#10
A14: 300109 | B14: 菩提祖师 | C14: 3001 | D14: 90 | E14: 8#10
A15: 300110 | B15: 菩提祖师 | C15: 3001 | D15: 100 | E15: 8#10
A16: 300301 | B16: 哪吒 | C16: 3003 | D16: 10 | E16: 8#5
A17: 300302 | B17: 哪吒 | C17: 3003 | D17: 20 | E17: 8#10
... A295: 304110 | B295: 月老 | C295: 3041 | D295: 100 | E295: 8#10
A296: 304201 | B296: 武财神 | C296: 3042 | D296: 10 | E296: 8#5
A297: 304202 | B297: 武财神 | C297: 3042 | D297: 20 | E297: 8#10
A298: 304203 | B298: 武财神 | C298: 3042 | D298: 30 | E298: 8#10
A299: 304204 | B299: 武财神 | C299: 3042 | D299: 40 | E299: 8#10
A300: 304205 | B300: 武财神 | C300: 3042 | D300: 50 | E300: 8#5
A301: 304206 | B301: 武财神 | C301: 3042 | D301: 60 | E301: 8#10
A302: 304207 | B302: 武财神 | C302: 3042 | D302: 70 | E302: 8#10
A303: 304208 | B303: 武财神 | C303: 3042 | D303: 80 | E303: 8#10
A304: 304209 | B304: 武财神 | C304: 3042 | D304: 90 | E304: 8#10
A305: 304210 | B305: 武财神 | C305: 3042 | D305: 100 | E305: 8#10
A306: 304301 | B306: 金池长老 | C306: 3043 | D306: 10 | E306: 8#5
A307: 304302 | B307: 金池长老 | C307: 3043 | D307: 20 | E307: 8#10
... A614: 307410 | B614: 江流儿 | C614: 3074 | D614: 100 | E614: 8#10

Sheet 统帅推荐牌组
A1: ID | D1: 卡组标题 | E1: 卡组内容 | F1: 卡组描述
A2: ID | D2: Title | E2: ComboList | F2: Desc
A3: 卡牌组合id | D3: 卡组的标题名称 | E3: 卡组展示的部将卡id 没有则空 | F3: 卡组的详细描述
A4: int | D4: string | E4: list:int | F4: stringnewline
A5: 0 ~ 999
A6: 1 | B6: 系统推荐 | C6: 菩提祖师 | D6: 妖族 | E6: 2031;2033;2034;2025;2057;2021;2022;2020;2091;2030;2018;2023;2024;2027;2029;2039;2060;2063;2049;2065;2061;2038;2050;2054;2058;2136;2019;2026;2032 | F6: 妖族通过提供属性成长的部将，来使时有牵绊能力的部将触发牵绊，进而使妖族的部将获得持续的属性成长。
A7: 2 | B7: 系统推荐 | C7: 九灵元圣 | D7: 罗刹 | E7: 2031;2033;2034;2025;2057;2021;2022;2020;2091;2030;2018;2023;2024;2027;2029;2039;2060;2063;2049;2065;2061;2038;2050;2054;2058;2136;2019;2026;2032 | F7: 罗刹牌组的介绍文本
A8: 3 | B8: 系统推荐 | C8: 魔礼海 | D8: 一夫当关 | E8: 2133;2081;2145;2146;2065;2056;2144;2143;2134;2135;2141;2136;2138;2061;2038;2050;2054;2058;2130;2131;2132;2133;2137;2140;2142;2031;2033;2034;2025;2057 | F8: 一夫当关牌组的介绍文本
A9: 4 | B9: 系统推荐 | C9: 牛魔王 | D9: 魔族 | E9: 2073;2078;2079;2080;2152;2048;2055;2057;2069;2072;2071;2076;2074;2081;2065;2061;2038;2050;2054;2058;2136;2066;2067;2068;2074;2075 | F9: 魔族牌组的介绍文本
A10: 5 | B10: 系统推荐 | C10: 天蓬元帅 | D10: 妖族 | E10: 2031;2033;2034;2025;2057;2021;2022;2020;2091;2030;2018;2023;2024;2027;2029;2039;2060;2063;2049;2065;2061;2038;2050;2054;2058;2136;2019;2026;2032 | F10: 妖族牌组的介绍文本
A11: 6 | B11: 系统推荐 | C11: 黄眉老佛 | D11: 罗刹 | E11: 2031;2033;2034;2025;2057;2021;2022;2020;2091;2030;2018;2023;2024;2027;2029;2039;2060;2063;2049;2065;2061;2038;2050;2054;2058;2136;2019;2026;2032 | F11: 罗刹牌组的介绍文本
A12: 7 | B12: 系统推荐 | C12: 魔礼红 | D12: 中立 | E12: 2053;2152;2057;2055;2062;2031;2058;2063;2099;2051;2047;2049;2029;2034;2079;2065;2061;2038;2050;2054;2048;2060;2046;2043;2041;2042;2045;2136;2036;2037;2039;2044 | F12: 中立牌组的介绍文本
A13: 8 | B13: 系统推荐 | C13: 金池长老 | D13: 灵山 | E13: 2053;2152;2057;2055;2062;2031;2058;2063;2099;2051;2047;2049;2029;2034;2079;2065;2061;2038;2050;2054;2048;2060;2046;2043;2041;2042;2045;2136;2036;2037;2039;2044 | F13: 灵山牌组的介绍文本
A14: 9 | B14: 系统推荐 | C14: 红孩儿 | D14: 龙族 | E14: 2133;2081;2145;2146;2065;2056;2144;2143;2134;2135;2141;2136;2138;2061;2038;2050;2054;2058;2130;2131;2132;2133;2137;2140;2142 | F14: 龙族牌组的介绍文本
A15: 10 | B15: 系统推荐 | C15: 嫦娥 | D15: 地府 | E15: 2031;2033;2034;2025;2057;2021;2022;2020;2091;2030;2018;2023;2024;2027;2029;2039;2060;2063;2049;2065;2061;2038;2050;2054;2058;2136;2019;2026;2032 | F15: 地府牌组的介绍文本
A16: 11 | B16: 系统推荐 | C16: 托塔天王 | D16: 妖族 | E16: 2031;2033;2034;2025;2057;2021;2022;2020;2091;2030;2018;2023;2024;2027;2029;2039;2060;2063;2049;2065;2061;2038;2050;2054;2058;2136;2019;2026;2032 | F16: 妖族牌组的介绍文本
A17: 12 | B17: 系统推荐 | C17: 玉皇大帝 | D17: 魔族 | E17: 2133;2081;2145;2146;2065;2056;2144;2143;2134;2135;2141;2136;2138;2061;2038;2050;2054;2058;2130;2131;2132;2133;2137;2140;2142;2031;2033;2034;2025;2057 | F17: 魔族牌组的介绍文本
... A44: 39 | B44: 系统推荐 | C44: 灵吉菩萨 | D44: 神族 | E44: 2133;2081;2145;2146;2065;2056;2144;2143;2134;2135;2141;2136;2138;2061;2038;2050;2054;2058;2130;2131;2132;2133;2137;2140;2142;2031;2033;2034;2025;2057 | F44: 神族牌组的介绍文本

Sheet 标签定义表
A1: ID | B1: 标签名称 | C1: 标签底图
A2: Id | B2: Name | C2: LableBg
A3: 标签ID | B3: 标签上的名称文本 | C3: 标签底图使用的资源路径
A4: int | B4: string | C4: string
A5: 备用行
A6: 1 | B6: 经济 | C6: Card/Lable2
A7: 2 | B7: 增强 | C7: Card/Lable1
A8: 3 | B8: 触发 | C8: Card/Lable1
A9: 4 | B9: 调遣 | C9: Card/Lable3
A10: 5 | B10: 赋予 | C10: Card/Lable1
A11: 6 | B11: 晋升 | C11: Card/Lable2
A12: 7 | B12: 进攻 | C12: Card/Lable1
A13: 8 | B13: 异术 | C13: Card/Lable3
