Workbook

Sheet 肉鸽战棋表
A1: 关卡ID | C1: 难度 | D1: 是否展示 | E1: 关卡开放 | F1: 排序 | G1: 必定参与势力 | H1: 参与势力 | I1: 解锁势力 | J1: 下一循环ID | K1: 参与势力数量 | L1: 通关开放势力 | M1: 是否开放锦囊 | N1: 回合ID | O1: 奖励 | P1: 每日限制过关次数
A2: ID | C2: Difficulty | D2: Show | E2: Open | F2: Sort | G2: MustCampId | H2: CampId | I2: UnlockCamp | J2: NextLevel | K2: CampNum | L2: CampOpenId | M2: MagicOpen | N2: RoundId | O2: Gift | P2: DailyLimit
A3: 打到第六关循环第六关 | C3: 难度定义 1.入门 2.简单 3.中等 4.困难 5.噩梦 6.活动 | D3: 0则不展示该难度 0.不展示 1.展示 | E3: 前置关卡ID | G3: 必定登场势力 | H3: 关卡参与的势力 每次通关完后跳到下一关并随机获取势力 | I3: 完成关卡后播放的解锁势力ID | J3: 下一循环ID | K3: 在该关卡中随机的势力数量 | L3: 通关开放的势力表现 | M3: 0.否 1.是 | N3: 回合表的组ID，同组有多个时，随机获取 | O3: 每日通关奖励道具ID#数量 | P3: 每日限制过关次数 拿了奖励才扣次数
A4: int | C4: int | D4: int | E4: int | F4: int | G4: list:int | H4: list:int | I4: int | J4: int | K4: int | L4: int | M4: int | N4: list:int | O4: string | P4: int
A5: 0 ~ 999
A6: 1 | B6: 入门 | C6: 1 | D6: 0 | F6: 1 | G6: 2;0 | H6: 6;8;7 | I6: 4 | J6: 2 | K6: 3 | L6: 4 | M6: 0 | N6: 1;2;3;4;5;6;7;8;9 | O6: 5#40 | Q6: 入门固定流程
A7: 2 | B7: 初级第一次 | C7: 2 | D7: 1 | E7: 1 | F7: 1 | G7: 2;0 | H7: 6;8;7;4 | I7: 3 | J7: 3 | K7: 3 | L7: 3 | M7: 1 | N7: 701;702;703;704;705;706;707;708;709;710;711;712;713;714;715 | O7: 5#40 | Q7: 简单第一次
A8: 3 | B8: 初级非第一次 | C8: 2 | D8: 1 | E8: 2 | F8: 2 | G8: 2;0 | H8: 6;8;7;4;3 | J8: 4 | K8: 3 | M8: 1 | N8: 701;702;703;704;705;706;707;708;709;710;711;712;713;714;715 | O8: 5#40 | Q8: 简单非第一次
A9: 4 | B9: 中等第一次 | C9: 3 | D9: 1 | E9: 2 | F9: 1 | G9: 2;0 | H9: 6;8;7;4;3 | I9: 5 | J9: 5 | K9: 3 | L9: 5 | M9: 1 | N9: 1301;1302;1303;1304;1305;1306;1307;1308;1309;1310;1311;1312;1313;1314;1315 | O9: 5#60 | Q9: 中等第一次
A10: 5 | B10: 中等非第一次→开始有随机节点 | C10: 3 | D10: 1 | E10: 4 | F10: 2 | G10: 2;0 | H10: 6;8;7;4;3;5 | I10: 9 | J10: 6 | K10: 4 | L10: 9 | M10: 1 | N10: 1301;1302;1303;1304;1305;1306;1307;1308;1309;1310;1311;1312;1313;1314;1315 | O10: 5#60 | Q10: 中等日常
A11: 6 | B11: 困难第一次 | C11: 4 | D11: 1 | E11: 4 | F11: 1 | G11: 2;0 | H11: 6;8;7;4;3;5;9 | I11: 1 | J11: 7 | K11: 4 | L11: 1 | M11: 1 | N11: 801;802;803;804;805;806;807;808;809;810;811;812;813;814;815 | O11: 5#80 | Q11: 困难第一次
A12: 7 | B12: 困难非第一次 | C12: 4 | D12: 1 | E12: 6 | F12: 2 | G12: 2;0 | H12: 6;8;7;4;3;5;9;1 | J12: 8 | K12: 4 | M12: 1 | N12: 801;802;803;804;805;806;807;808;809;810;811;812;813;814;815 | O12: 5#80 | Q12: 困难日常
A13: 8 | B13: 噩梦第一次 | C13: 5 | D13: 1 | E13: 6 | F13: 1 | G13: 2;0 | H13: 6;8;7;4;3;5;9;1 | J13: 8 | K13: 4 | M13: 1 | N13: 901;902;903;904;905;906;907;908;909;910;911;912;913;914;915 | O13: 5#100 | Q13: 噩梦第一次 | R13: 噩梦第一次
A14: 9 | B14: 噩梦非第一次 | C14: 5 | D14: 1 | E14: 8 | F14: 2 | G14: 2;0 | H14: 6;8;7;4;3;5;9;1 | J14: 8 | K14: 4 | M14: 1 | N14: 1001;1002;1003;1004;1005;1006;1007;1008;1009;1010;1011;1012;1013;1014;1015 | O14: 5#100 | Q14: 噩梦日常 | R14: 噩梦日常
A15: 10 | B15: 端午第一次 | C15: 6 | D15: 0 | E15: 1 | F15: 1 | G15: 2;0 | H15: 6;8;7;4;3;5;9;1 | J15: 8 | K15: 4 | M15: 1 | N15: 1101;1102;1103;1104;1105;1106;1107;1108;1109;1110;1111;1112;1113;1114;1115 | O15: 19#3 | Q15: 活动第一次
A16: 11 | B16: 端午非第一次 | C16: 6 | D16: 0 | E16: 10 | F16: 2 | G16: 2;0 | H16: 6;8;7;4;3;5;9;1 | J16: 8 | K16: 4 | M16: 1 | N16: 1201;1202;1203;1204;1205;1206;1207;1208;1209;1210;1211;1212;1213;1214;1215 | O16: 19#3 | P16: 1 | Q16: 活动日常

Sheet 教学引导关
A1: 关卡ID | C1: 势力ID | D1: 势力名称 | E1: 流派名称 | F1: 核心部将 | G1: 是否开放锦囊 | H1: 回合组ID | I1: 奖励 | J1: 显示文本1 | K1: 大圣ID | L1: 大圣血量 | M1: 初始商店 | N1: 商店会出现的牌 | O1: 友方登场部将 | P1: 持有手牌 | Q1: 文本框显示位置 | R1: 显示文本2 | S1: 过关目标 | T1: 给予金币数 | U1: 商店等级
A2: ID | C2: CampId | D2: CampName | E2: GenreName | F2: KeyCard | G2: MagicOpen | H2: RoundId | I2: Gift | J2: Text1 | K2: HeroId | L2: HeroHp | M2: InitialShop | N2: CardID | O2: MyCard | P2: HoldCard | Q2: TextPosition | R2: Text2 | S2: Goal | T2: GoldNum | U2: ShopLevel
C3: 关卡教学的势力ID，见K_部将卡牌总表-卡牌势力表 | D3: 教学页面显示 | E3: 阵营流派名称 | F3: 核心的部将，位于教学页面 | G3: 0.否 1.是 | H3: 回合表的组ID，同组有多个时，随机获取 | I3: 通关奖励道具ID#数量 | J3: 流派简介文本，位于教学页面(进关前) | K3: 友方出战的大圣 | L3: 友方大圣初始血量 | M3: 第一回合商店初始出现的牌ID | N3: 商店中会出现的牌ID | O3: 第一回合进教学关时己方的登场部将，部将ID#攻击#生命#法强 | P3: 第一回合进教学关时手上的手牌 Type#ID， Type区分部将和神通，0为部将，1为神通 ID是对应部将/神通的ID，见K_部将卡牌总表/K_卡牌_锦囊 | Q3: x y | R3: 第一回合的引导文本 | S3: 过关目标展示 | T3: 回合数#金币数 | U3: 初始商店等级
A4: int | C4: int | D4: string | E4: string | F4: list:int | G4: int | H4: list:int | I4: string | J4: string | K4: int | L4: int | M4: list:int | N4: list:int | O4: list:string | P4: list:string | Q4: list:float | R4: string | S4: string | T4: list:string | U4: int
A5: 0 ~ 999
A6: 1001 | C6: 6 | D6: 花果山 | E6: 后援神通流 | F6: 2031;2029;2160;2033;2057 | J6: 【后援】触发跑山猢狲给予的神通奖励，释放神通触发心猿的提高友军生命值效果，从而触发【协战】效果提高全体属性。 | L6: 1 | S6: 击败3个敌人(0/3)
C7: 6 | D7: 花果山 | E7: 马流上阵流 | F7: 2031;2030;2033 | J7: 当场上有马流元帅时不断上阵花果山部将来获得属性增益，并触发【协战】效果提高全体属性。 | L7: 1
C8: 6 | D8: 花果山 | E8: 登场神通流 | F8: 2031;2160;2033;2055 | J8: 金福星能带来大量额外经济，配合袁守诚和天庭的金丹道尊能获得大量神通，释放神通触发参禅心猿的效果来触发【协战】效果提高全体属性。 | L8: 1
C9: 8 | D9: 天庭 | E9: 登场斗姆流 | F9: 2098;2093;2097;2055 | J9: 用王灵官帮助快速组建阵容；不断打出具有登场效果的部将，配合福星多段触发斗姆元君的效果提高全体属性。 | L9: 1
C10: 8 | D10: 天庭 | E10: 护盾流 | F10: 2099;2098;2094 | J10: 战斗中友方部将失去护盾触发李天王的增益效果，再配合蟠桃仙女实现多次补盾来获得更多次增益是护盾流的核心。 | L10: 1
C11: 2 | D11: 大唐 | E11: 唐王混合流 | F11: 2053;2152;2057;2055 | J11: 孔雀公主的【后援】效果配合禄星能多次获取优质大唐部将，上阵大唐部将以触发唐王的增益效果，可携带其他势力的核心牌以增强战力，如美猴王。 | L11: 1
C12: 4 | D12: 龙宫 | E12: 残念流 | F12: 2133;2081;2145;2056;2146 | J12: 是一套偏前中期的强势阵容，龙魂高攻低血。虾兵的【残念】能召唤一条神龙并提高龙魂攻击力，配合寿星和地藏菩萨也能大量召唤神龙 | L12: 1
C13: 4 | D13: 龙宫 | E13: 后援流 | F13: 2140;2134;2055;2057;2141;2145 | J13: 龙宫流派中身材和战力较为强势的流派，通过部将的【后援】来提高龙魂属性，蚌壳精帮助快速组建阵容，小鼍龙的【后援】效果触发鱼总兵的登场效果，海螺姑娘召唤神龙 | L13: 1
C14: 4 | D14: 龙宫 | E14: 下毒流 | F14: 2138;2133;2081;2146;2056 | J14: 不算是常规传统龙宫阵容，通过珊瑚的【猛毒】和【残念】给友方部将贴毒的技能效果来克制傻大个阵容 | L14: 1
C15: 5 | D15: 地府 | E15: 怨魂频率流 | F15: 2016;2015;2081;2010;2056 | J15: 怨魂的【残念】效果与寿星搭配能达成倍率成长，以此为核心用阎罗王的鼓舞触发【残念】和地藏王菩萨的先手触发【残念】效果提高触发【残念】频次 | L15: 1
C16: 5 | D16: 地府 | E16: 频率鬼魂流 | F16: 2027;2009;2012;2057;2017 | J16: 鬼魂神通能够给地府部将提供全局的属性增益，通过蝶妖增加鬼魂的属性增益加成，再配合上夜游神【后援】获取鬼魂神通和女帝【业报】使用鬼魂神通的效果来提高战力 | L16: 1
C17: 7 | D17: 狮驼岭 | E17: 神通酒僧流 | F17: 2071;2027;2189;2077;2056 | J17: 依靠白面熊猫【残念】获取的杨枝甘露，配合蝶妖增加杨枝甘露的增幅属性，使用杨枝甘露触发斗酒僧的效果养大友方狮驼岭部将 | L17: 1
C18: 7 | D18: 狮驼岭 | E18: 后援商店流 | F18: 2078;2152;2057;2080 | J18: 孔雀公主的【后援】效果配合禄星获取狮驼岭部将，不断上阵狮驼岭部将让青狮精吞噬商店中部将的属性，大喇叭的【后援】则进一步提高整体战力 | L18: 1
... C24: 3 | D24: 灵山 | E24: 苦修流 | F24: 2044;2056;2117;2124;2129 | J24: 利用缺心眼的【残念】对多名友方部将造成伤害，并用寿星重复触发，快速累计【苦修】次数；小和尚和济公禅师将【苦修】转化为自身与全体属性成长，大日如来则补充法术输出。 | L24: 1

Sheet 回合表
A1: 回合ID | B1: 组ID | C1: 出现权重 | E1: 大圣ID | F1: 大圣生命 | G1: 大圣对统帅造成的伤害 | H1: 是否为初始 | I1: 使用场景 | J1: 回合图标 | K1: 回合图标类型 | L1: 是否重来 | M1: 回合名称 | N1: 是否可升级商店 | O1: 可选法宝 | P1: 登场部将 | Q1: 禁用锦囊 | R1: 首通解锁大圣 | S1: 金币数量
A2: RoundId | B2: GroupId | C2: Weight | E2: HeroId | F2: HeroHp | G2: HeroAttack | H2: IsInitial | I2: UseMap | J2: RoundIcon | K2: RoundIconType | L2: Again | M2: RoundName | N2: ShopLv | O2: MagicWeapen | P2: Card | Q2: ForbidMagic | R2: UnlockHero | S2: GoldNum
B3: 同组进行随机 | E3: 回合出现的大圣ID | F3: 出现的大圣生命 | G3: 如果Ai获胜，对玩家造成的基础伤害，替代商店等级 | H3: 若是，则为首次通关时必出 0.否 1.是 | I3: 自走棋棋盘ID | J3: 回合图标路径 | K3: 1.小节点 2.大节点 | L3: 0.不重来，打了就往下走 1.重来，不打死就再来 | M3: 回合下面的名称 | N3: 若是，进入回合后则可以进行一次商店升级，出升级提示 0.否 1.是 | O3: 回合可选法宝ID | P3: 部将ID#攻击#生命#法强;部将ID#攻击#生命#法强 | Q3: 禁用锦囊 先根据商店等级随机，然后剔除禁用的。 | R3: 首次通过回合解锁的大圣ID | S3: 超过回合取最大回合的金币
A4: int | B4: int | C4: int | E4: int | F4: int | G4: int | H4: int | I4: int | J4: string | K4: int | L4: int | M4: string | N4: int | O4: list:int | P4: list:string | Q4: list:int | R4: int | S4: int
A5: 0 ~ 999
A6: 101 | B6: 1 | C6: 100 | D6: 山贼弓手 | E6: 5034 | F6: 1 | G6: 1 | H6: 1 | I6: 8 | J6: rogue/icon_rogueround_0 | K6: 1 | L6: 0 | M6: 1-1 | N6: 0 | P6: 15001#1#2#0 | Q6: 2051;2071;2061;6061
A7: 201 | B7: 2 | C7: 100 | D7: 大唐侍卫 | E7: 5045 | F7: 1 | G7: 1 | H7: 1 | I7: 8 | J7: rogue/icon_rogueround_0 | K7: 1 | L7: 0 | M7: 1-2 | N7: 0 | P7: 1036#1#2#0 | Q7: 2051;2071;2061;6061
A8: 301 | B8: 3 | C8: 100 | D8: 孙悟空 | E8: 5003 | F8: 1 | G8: 2 | H8: 1 | I8: 8 | J8: rogue/icon_rogueround_4 | K8: 2 | L8: 1 | M8: 五行山 | N8: 0 | P8: 1021#3#3#0;1034#3#3#0 | Q8: 2051;2071;2061;6061
A9: 401 | B9: 4 | C9: 100 | D9: 乞丐 | E9: 5046 | F9: 1 | G9: 2 | H9: 1 | I9: 8 | J9: rogue/icon_rogueround_0 | K9: 1 | L9: 0 | M9: 2-1 | N9: 0 | P9: 1035#7#7#0;1060#3#3#0;15002#3#3#0 | Q9: 2051;2071;2061;6061
A10: 501 | B10: 5 | C10: 100 | D10: 独角鬼王 | E10: 5048 | F10: 1 | G10: 2 | H10: 1 | I10: 8 | J10: rogue/icon_rogueround_0 | K10: 1 | L10: 0 | M10: 2-2 | N10: 0 | P10: 1002#4#7#0;1003#4#7#0;1007#4#7#0 | Q10: 2051;2071;2061;6061
A11: 601 | B11: 6 | C11: 100 | D11: 黑熊精 | E11: 5009 | F11: 1 | G11: 3 | H11: 1 | I11: 3 | J11: rogue/icon_rogueround_1 | K11: 2 | L11: 1 | M11: 黑风洞 | N11: 0 | P11: 1163#2#2#0;1075#5#5#0;15010#12#12#0;1077#6#6#0;1163#2#2#0 | Q11: 2051;2071;2061;6061
A12: 701 | B12: 7 | C12: 100 | D12: 东海龙王 | E12: 5049 | F12: 1 | G12: 3 | H12: 1 | I12: 8 | J12: rogue/icon_rogueround_0 | K12: 1 | L12: 0 | M12: 3-1 | N12: 0 | P12: 1133#4#3#0;1133#4#3#0;1146#5#5#0;1135#3#4#0;1135#3#4#0 | Q12: 2051;2071;2061;6061
A13: 801 | B13: 8 | C13: 100 | D13: 袁守城 | E13: 5015 | F13: 1 | G13: 3 | H13: 1 | I13: 8 | J13: rogue/icon_rogueround_0 | K13: 1 | L13: 0 | M13: 3-2 | N13: 0 | P13: 1062#12#12#0;1046#8#8#0;1036#4#4#0;1036#6#6#0;1046#6#6#0;1062#12#12#0 | Q13: 2051;2071;2061;6061
A14: 901 | B14: 9 | C14: 100 | D14: 红孩儿 | E14: 5013 | F14: 1 | G14: 4 | H14: 1 | I14: 3 | J14: rogue/icon_rogueround_1 | K14: 2 | L14: 1 | M14: 火云洞 | N14: 0 | P14: 15019#21#15#0;15019#21#15#0;1077#15#15#0;15020#12#3#0;15020#12#3#0;1077#15#15#0 | Q14: 2051;2071;2061;6061
A15: 1001 | B15: 10 | C15: 100 | D15: 敖丙 | E15: 5021 | F15: 1 | G15: 4 | H15: 1 | I15: 3 | J15: rogue/icon_rogueround_0 | K15: 1 | L15: 0 | M15: 4-1 | N15: 0 | P15: 1133#43#39#0;1135#39#35#0;1134#48#48#0;1138#23#25#0;1138#23#25#0;1056#15#7#0;1137#9#9#0 | Q15: 2051;2071;2061;6061
A16: 1101 | B16: 11 | C16: 100 | D16: 孔雀公主 | E16: 5022 | F16: 1 | G16: 4 | H16: 1 | I16: 3 | J16: rogue/icon_rogueround_0 | K16: 1 | L16: 0 | M16: 4-2 | N16: 0 | P16: 1078#105#95#0;1073#85#75#0;1072#49#49#0;1070#59#59#0;1071#69#69#0;1058#9#9#0;1058#9#9#0 | Q16: 2051;2071;2061;6061
A17: 1201 | B17: 12 | C17: 100 | D17: 大鹏金翅鸟 | E17: 5020 | F17: 1 | G17: 5 | H17: 1 | I17: 3 | J17: rogue/icon_rogueround_4 | K17: 2 | L17: 1 | M17: 狮驼岭 | N17: 0 | P17: 15036#110#115#0;15037#100#105#0;1079#106#65#0;15038#48#48#0;15038#36#36#0;1070#24#24#0;1071#24#24#0 | Q17: 2051;2071;2061;6061
... A177: 10007 | B177: 1007 | C177: 100 | D177: 青牛精 | E177: 5058 | F177: 1 | G177: 3 | H177: 1 | I177: 8 | J177: rogue/icon_rogueround_0 | K177: 1 | L177: 0 | M177: 3-1 | N177: 0 | P177: 1070#15#12#0;1071#9#12#0;15078#25#25#0;1079#15#8#0;1079#15#8#0;1078#12#20#0 | Q177: 2051;2071;2061;6061
A178: 10008 | B178: 1008 | C178: 100 | D178: =VLOOKUP(E178,[1]统帅!$A:$D,4,0) -> 红鳞大蟒 | E178: 5060 | F178: 1 | G178: 3 | H178: 1 | I178: 8 | J178: rogue/icon_rogueround_0 | K178: 1 | L178: 0 | M178: 3-2 | N178: 0 | P178: 16062#3#6#0;1024#20#30#0;1027#25#25#0;15080#40#40#0;1024#20#30#0;16062#3#6#0;1027#25#25#0 | Q178: 2051;2071;2061;6061
A179: 10009 | B179: 1009 | C179: 100 | D179: 红孩儿 | E179: 5013 | F179: 1 | G179: 4 | H179: 1 | I179: 2 | J179: rogue/icon_rogueround_1 | K179: 2 | L179: 1 | M179: 火云洞 | N179: 0 | P179: 15019#45#45#0;15019#45#45#0;1109#35#35#0;1106#15#30#0;15020#35#5#0;15020#35#5#0;1077#30#30#0 | Q179: 2051;2071;2061;6061
A180: 10010 | B180: 1010 | C180: 100 | D180: 万岁狐仙 | E180: 5059 | F180: 1 | G180: 4 | H180: 1 | I180: 8 | J180: rogue/icon_rogueround_0 | K180: 1 | L180: 0 | M180: 4-1 | N180: 0 | P180: 2031#235#110#0;1033#140#140#0;1026#120#140#0;15079#170#170#0;1034#65#65#0;1057#25#25#0;1029#40#40#0 | Q180: 2051;2071;2061;6061
A181: 10011 | B181: 1011 | C181: 100 | D181: 菩提祖师 | E181: 5032 | F181: 1 | G181: 4 | H181: 1 | I181: 8 | J181: rogue/icon_rogueround_0 | K181: 1 | L181: 0 | M181: 4-2 | N181: 0 | P181: 1098#255#150#0;1098#255#150#0;1099#195#195#0;1099#195#195#0;1094#65#65#0;1094#65#65#0;1090#150#300#0 | Q181: 2051;2071;2061;6061
A182: 10012 | B182: 1012 | C182: 100 | D182: 盘丝大仙 | E182: 5066 | F182: 1 | G182: 5 | H182: 1 | I182: 6 | J182: rogue/icon_rogueround_4 | K182: 2 | L182: 1 | M182: 盘丝洞 | N182: 0 | P182: 15087#255#255#0;15088#110#110#0;15085#300#255#0;15086#425#425#0;15085#300#255#0;15088#110#110#0;15087#255#255#0 | Q182: 2051;2071;2061;6061
A183: 10013 | B183: 1013 | C183: 100 | D183: 刑天 | E183: 5042 | F183: 1 | G183: 5 | H183: 1 | I183: 8 | J183: rogue/icon_rogueround_0 | K183: 1 | L183: 0 | M183: 5-1 | N183: 0 | P183: 1111#765#425#0;2114#425#680#0;2100#425#425#0;2112#640#680#0;2107#340#680#0;2107#340#680#0;2109#425#425#0 | Q183: 2051;2071;2061;6061
A184: 10014 | B184: 1014 | C184: 100 | D184: 后羿 | E184: 5061 | F184: 10 | G184: 5 | H184: 1 | I184: 8 | J184: rogue/icon_rogueround_0 | K184: 1 | L184: 0 | M184: 5-2 | N184: 0 | P184: 2082#510#680#170;15019#510#680#0;2109#510#680#170;15081#2125#2125#0;2109#510#680#170;15019#510#680#170;2082#510#680#170 | Q184: 2051;2071;2061;6061
A185: 10015 | B185: 1015 | C185: 100 | D185: 神怒三太子 | E185: 5062 | F185: 30 | G185: 6 | H185: 1 | I185: 2 | J185: rogue/icon_rogueround_4 | K185: 2 | L185: 1 | M185: 灵山 | N185: 0 | P185: 16082#2040#1360#0;15083#1020#510#0;15084#510#1020#0;2090#765#765#0;15083#1020#510#0;15084#510#1020#0;2090#765#765#0 | Q185: 2051;2071;2061;6061
A186: 11001 | B186: 1001 | C186: 100 | D186: 济公禅师 | E186: 5050 | F186: 1 | G186: 1 | H186: 1 | I186: 8 | J186: rogue/icon_rogueround_0 | K186: 1 | L186: 0 | M186: 1-1 | N186: 0 | P186: 1067#2#2#0 | Q186: 2051;2071;2061;6061
A187: 11002 | B187: 1002 | C187: 100 | D187: 混世魔王 | E187: 5037 | F187: 1 | G187: 1 | H187: 1 | I187: 8 | J187: rogue/icon_rogueround_0 | K187: 1 | L187: 0 | M187: 1-2 | N187: 0 | P187: 1100#3#4#0 | Q187: 2051;2071;2061;6061
A188: 11003 | B188: 1003 | C188: 100 | D188: 白龙马 | E188: 5005 | F188: 1 | G188: 2 | H188: 1 | I188: 9 | J188: rogue/icon_rogueround_4 | K188: 2 | L188: 1 | M188: 鹰愁涧 | N188: 0 | P188: 1133#3#2#0;1135#2#3#0 | Q188: 2051;2071;2061;6061
A189: 11004 | B189: 1004 | C189: 100 | D189: 黄袍怪 | E189: 5019 | F189: 1 | G189: 2 | H189: 1 | I189: 8 | J189: rogue/icon_rogueround_0 | K189: 1 | L189: 0 | M189: 2-1 | N189: 0 | P189: 1020#3#3#0;1018#3#3#0;1020#3#3#0;1021#6#6#0;1021#6#6#0 | Q189: 2051;2071;2061;6061
A190: 11005 | B190: 1005 | C190: 100 | D190: 修罗尊者 | E190: 5053 | F190: 10 | G190: 2 | H190: 1 | I190: 8 | J190: rogue/icon_rogueround_0 | K190: 1 | L190: 0 | M190: 2-2 | N190: 0 | P190: 1100#12#9#0;1114#12#9#0;1106#8#8#0;1104#4#4#0 | Q190: 2051;2071;2061;6061
... A200: 11015 | B200: 1015 | C200: 100 | D200: 无天佛祖 | E200: 5033 | F200: 30 | G200: 6 | H200: 1 | I200: 2 | J200: rogue/icon_rogueround_4 | K200: 2 | L200: 1 | M200: 灵山 | N200: 0 | P200: 15073#325#325#25;2126#385#385#35;15075#400#400#30;15072#1500#2300#30;15075#400#400#30;2126#375#375#30;15073#325#325#25 | Q200: 2051;2071;2061;6061
A201: 12011 | B201: 1101 | C201: 100 | D201: =VLOOKUP(E201,[1]统帅!$A:$D,4,0) -> 济公禅师 | E201: 5050 | F201: 1 | G201: 1 | H201: 1 | I201: 8 | J201: rogue/icon_rogueround_0 | K201: 1 | L201: 0 | M201: 1-1 | N201: 0 | P201: 1067#2#2#0 | Q201: 2051;2071;2061;6061
A202: 12021 | B202: 1102 | C202: 100 | D202: =VLOOKUP(E202,[1]统帅!$A:$D,4,0) -> 混世魔王 | E202: 5037 | F202: 1 | G202: 1 | H202: 1 | I202: 8 | J202: rogue/icon_rogueround_0 | K202: 1 | L202: 0 | M202: 1-2 | N202: 0 | P202: 1100#3#4#0 | Q202: 2051;2071;2061;6061
A203: 12031 | B203: 1103 | C203: 100 | D203: =VLOOKUP(E203,[1]统帅!$A:$D,4,0) -> 沙悟净 | E203: 5006 | F203: 1 | G203: 2 | H203: 1 | I203: 9 | J203: rogue/icon_rogueround_4 | K203: 2 | L203: 1 | M203: 流沙河 | N203: 0 | P203: 1051#3#6#0;1001#2#1#0;1003#1#3#0 | Q203: 2051;2071;2061;6061
A204: 12041 | B204: 1104 | C204: 100 | D204: =VLOOKUP(E204,[1]统帅!$A:$D,4,0) -> 黄袍怪 | E204: 5019 | F204: 1 | G204: 2 | H204: 1 | I204: 8 | J204: rogue/icon_rogueround_0 | K204: 1 | L204: 0 | M204: 2-1 | N204: 0 | P204: 1020#3#3#0;1018#3#3#0;1020#3#3#0;1021#6#6#0;1021#6#6#0 | Q204: 2051;2071;2061;6061
A205: 12051 | B205: 1105 | C205: 100 | D205: =VLOOKUP(E205,[1]统帅!$A:$D,4,0) -> 修罗尊者 | E205: 5053 | F205: 10 | G205: 2 | H205: 1 | I205: 8 | J205: rogue/icon_rogueround_0 | K205: 1 | L205: 0 | M205: 2-2 | N205: 0 | P205: 1100#12#9#0;1114#12#9#0;1106#8#8#0;1104#4#4#0 | Q205: 2051;2071;2061;6061
A206: 12061 | B206: 1106 | C206: 100 | D206: =VLOOKUP(E206,[1]统帅!$A:$D,4,0) -> 人参果树 | E206: 5067 | F206: 1 | G206: 3 | H206: 1 | I206: 8 | J206: rogue/icon_rogueround_1 | K206: 2 | L206: 1 | M206: 五庄观 | N206: 0 | P206: 16090#12#6#0;16089#30#30#0;16090#12#6#0 | Q206: 2051;2071;2061;6061
A207: 12071 | B207: 1107 | C207: 100 | D207: =VLOOKUP(E207,[1]统帅!$A:$D,4,0) -> 太白金星 | E207: 5014 | F207: 1 | G207: 3 | H207: 1 | I207: 8 | J207: rogue/icon_rogueround_0 | K207: 1 | L207: 0 | M207: 3-1 | N207: 0 | P207: 1098#35#15#0;1084#15#12#0;1084#15#12#0;1090#10#10#0 | Q207: 2051;2071;2061;6061
A208: 12081 | B208: 1108 | C208: 100 | D208: =VLOOKUP(E208,[1]统帅!$A:$D,4,0) -> 黄风大圣 | E208: 5010 | F208: 1 | G208: 3 | H208: 1 | I208: 8 | J208: rogue/icon_rogueround_0 | K208: 1 | L208: 0 | M208: 3-2 | N208: 0 | P208: 2067#2#2#4;2119#6#6#4;2067#2#2#4;2119#6#6#4;2117#4#4#4;2117#3#6#4 | Q208: 2051;2071;2061;6061
...

Sheet 难度定义
A1: ID | B1: 难度 | C1: 是否展示 | D1: 排序 | E1: 首通奖励 | F1: 角标文字 | G1: 开启时间 | H1: 关闭时间
A2: ID | B2: Difficulty | C2: Show | D2: Shot | E2: FirstGift | F2: LabelText | G2: BeginTime | H2: EndTime
A3: 打到第六关循环第六关 | B3: 难度定义 1.入门 2.简单 3.困难 4.噩梦 | C3: 0则不展示该难度 0.不展示 1.展示 | D3: 小的在前 | E3: 首通给与的奖励 | F3: 角标文字 | G3: 开启时间 | H3: 关闭时间
A4: int | B4: string | C4: int | D4: int | E4: string | F4: string | G4: string | H4: string
A5: 0 ~ 999
A6: 1 | B6: 入门 | C6: 0 | D6: 1 | E6: 8#40
A7: 2 | B7: 简单 | C7: 1 | D7: 2 | E7: 8#40
A8: 3 | B8: 中等 | C8: 1 | D8: 3 | E8: 8#60
A9: 4 | B9: 困难 | C9: 1 | D9: 4 | E9: 8#80
A10: 5 | B10: 噩梦 | C10: 1 | D10: 5 | E10: 8#100
A11: 6 | B11: 端午 | C11: 0 | D11: 6 | E11: 19#3 | F11: 端午 | G11: 2026-05-20 00:00:01 | H11: 2026-06-27 23:59:59
